Workbook
Name 결석훈련생명단: '훈련일지(2)'!$E$23:$O$23
Name 결석훈련생명단: '훈련일지(1)'!$E$24:$O$24
Name 공휴일: 기본입력!$J$2:$J$33
Name 과목1: 기본입력!$B$9
Name 과목10: 기본입력!$B$18
Name 과목11: 기본입력!$B$19
Name 과목12: 기본입력!$B$20
Name 과목13: 기본입력!$B$21
Name 과목14: 기본입력!$B$22
Name 과목15: 기본입력!$B$23
Name 과목16: 기본입력!$B$24
Name 과목17: 기본입력!$B$25
Name 과목18: 기본입력!$B$26
Name 과목19: 기본입력!$B$27
Name 과목2: 기본입력!$B$10
Name 과목20: 기본입력!$B$28
Name 과목21: 기본입력!$B$29
Name 과목22: 기본입력!$B$30
Name 과목23: 기본입력!$B$31
Name 과목24: 기본입력!$B$32
Name 과목25: 기본입력!$B$33
Name 과목3: 기본입력!$B$11
Name 과목4: 기본입력!$B$12
Name 과목5: 기본입력!$B$13
Name 과목6: 기본입력!$B$14
Name 과목7: 기본입력!$B$15
Name 과목8: 기본입력!$B$16
Name 과목9: 기본입력!$B$17
Name 누적시수1: 기본입력!$D$9
Name 누적시수10: 기본입력!$D$18
Name 누적시수11: 기본입력!$D$19
Name 누적시수12: 기본입력!$D$20
Name 누적시수13: 기본입력!$D$21
Name 누적시수14: 기본입력!$D$22
Name 누적시수15: 기본입력!$D$23
Name 누적시수16: 기본입력!$D$24
Name 누적시수17: 기본입력!$D$25
Name 누적시수18: 기본입력!$D$26
Name 누적시수19: 기본입력!$D$27
Name 누적시수2: 기본입력!$D$10
Name 누적시수20: 기본입력!$D$28
Name 누적시수21: 기본입력!$D$29
Name 누적시수22: 기본입력!$D$30
Name 누적시수23: 기본입력!$D$31
Name 누적시수24: 기본입력!$D$32
Name 누적시수25: 기본입력!$D$33
Name 누적시수3: 기본입력!$D$11
Name 누적시수4: 기본입력!$D$12
Name 누적시수5: 기본입력!$D$13
Name 누적시수6: 기본입력!$D$14
Name 누적시수7: 기본입력!$D$15
Name 누적시수8: 기본입력!$D$16
Name 누적시수9: 기본입력!$D$17
Name 시작일: 기본입력!$H$2
Name 시작주월요일: 기본입력!$H$6
Name 조퇴훈련생명단: '훈련일지(2)'!$E$25:$O$25
Name 조퇴훈련생명단: '훈련일지(1)'!$E$26:$O$26
Name 종료일: 기본입력!$H$4
Name 지각훈련생명단: '훈련일지(2)'!$E$21:$O$21
Name 지각훈련생명단: '훈련일지(1)'!$E$22:$O$22

Sheet 기본입력
A1: 훈련과목명 | C1: 인공지능(AI),빅데이터 활용 웹솔루션 개발자 양성(Python, Java) | H1: 시작일 | J1: 공휴일(주말제외)
A2: 훈련기간 | C2: 2025.09.22~2026.03.25 | H2: 45922 | J2: 45884
A3: 시간/일/일평균시간 | C3: (6개월. 122일. 976시간. 일 8.0시간) | H3: 종료일 | J3: 2025-10-03
H4: 46106 | J4: 2025-10-06
A5: 시설(강의실명) | C5: 시설코드 | H5: 시작주 월요일 | J5: 45937
A6: 1교육실(실습겸용강의실) | C6: 1교육실(실습겸용강의실)_243089 | H6: 45922 | J6: 45938
J7: 45939 | M7: 훈련교사정보
A8: 번호 | B8: 과목명 | C8: 시수 | D8: 누적시수 | E8: 훈련교사코드 | F8: 과목코드 | J8: 46016 | L8: 훈련교사 | M8: 훈련교사 | N8: 코드
A9: =IF(B9="","",ROW()-8) -> 1 | B9: 웹 애플리케이션 개발 | C9: 80 | D9: =IF(과목1="","",SUM($C$9:$C9)) -> 80 | E9: =IF(L9="","",VLOOKUP(L9,$M$9:$N$12,2,FALSE)) -> 양현수_53778 | F9: 웹 애플리케이션 개발__3 | J9: 46023 | L9: [200102]양현수 | M9: [200102]김은수 | N9: 김은수_52618
A10: =IF(B10="","",ROW()-8) -> 2 | B10: 웹&콘텐츠 서비스 개발 | C10: 40 | D10: =IF(과목2="","",SUM($C$9:$C10)) -> 120 | E10: =IF(L10="","",VLOOKUP(L10,$M$9:$N$12,2,FALSE)) -> 양현수_53778 | F10: 웹&콘텐츠 서비스 개발__4 | J10: 46069 | L10: [200102]양현수 | M10: [200102]박기태 | N10: 박기태_1947477
A11: =IF(B11="","",ROW()-8) -> 3 | B11: SQL 및 데이터 모델링 | C11: 72 | D11: =IF(과목3="","",SUM($C$9:$C11)) -> 192 | E11: =IF(L11="","",VLOOKUP(L11,$M$9:$N$12,2,FALSE)) -> 양현수_53778 | F11: SQL 및 데이터 모델링__5 | J11: 46070 | L11: [200102]양현수 | M11: [200102]양현수 | N11: 양현수_53778
A12: =IF(B12="","",ROW()-8) -> 4 | B12: AI개발 기초 | C12: 100 | D12: =IF(과목4="","",SUM($C$9:$C12)) -> 292 | E12: =IF(L12="","",VLOOKUP(L12,$M$9:$N$12,2,FALSE)) -> 양현수_53778 | F12: AI개발 기초__1 | J12: 46071 | L12: [200102]양현수
A13: =IF(B13="","",ROW()-8) -> 5 | B13: 인공지능 프로그래밍 | C13: 128 | D13: =IF(과목5="","",SUM($C$9:$C13)) -> 420 | E13: =IF(L13="","",VLOOKUP(L13,$M$9:$N$12,2,FALSE)) -> 양현수_53778 | F13: 인공지능 프로그래밍__2 | J13: 46083 | L13: [200102]양현수
A14: =IF(B14="","",ROW()-8) -> 6 | B14: Advanced 프로젝트 | C14: 104 | D14: =IF(과목6="","",SUM($C$9:$C14)) -> 524 | E14: =IF(L14="","",VLOOKUP(L14,$M$9:$N$12,2,FALSE)) -> 양현수_53778 | F14: Advanced 프로젝트_9 | L14: [200102]양현수
A15: =IF(B15="","",ROW()-8) -> 7 | B15: 빅데이터 분석 및 시각화 | C15: 40 | D15: =IF(과목7="","",SUM($C$9:$C15)) -> 564 | E15: =IF(L15="","",VLOOKUP(L15,$M$9:$N$12,2,FALSE)) -> 양현수_53778 | F15: 빅데이터 분석 및 시각화__6 | L15: [200102]양현수
A16: =IF(B16="","",ROW()-8) -> 8 | B16: 빅데이터 시스템 구축 | C16: 80 | D16: =IF(과목8="","",SUM($C$9:$C16)) -> 644 | E16: =IF(L16="","",VLOOKUP(L16,$M$9:$N$12,2,FALSE)) -> 양현수_53778 | F16: 빅데이터 시스템 구축__7 | L16: [200102]양현수
A17: =IF(B17="","",ROW()-8) -> 9 | B17: 빅데이터 플랫폼 개발 | C17: 60 | D17: =IF(과목9="","",SUM($C$9:$C17)) -> 704 | E17: =IF(L17="","",VLOOKUP(L17,$M$9:$N$12,2,FALSE)) -> 양현수_53778 | F17: 빅데이터 플랫폼 개발__8 | L17: [200102]양현수
A18: =IF(B18="","",ROW()-8) -> 10 | B18: Final 프로젝트 | C18: 256 | D18: =IF(과목10="","",SUM($C$9:$C18)) -> 960 | E18: =IF(L18="","",VLOOKUP(L18,$M$9:$N$12,2,FALSE)) -> 양현수_53778 | F18: Final 프로젝트__10 | L18: [200102]양현수
A19: =IF(B19="","",ROW()-8) -> 11 | B19: 산업체특강 , 프로젝트 발표(시연), 수료식 | C19: 4 | D19: =IF(과목11="","",SUM($C$9:$C19)) -> 964 | E19: =IF(L19="","",VLOOKUP(L19,$M$9:$N$12,2,FALSE)) -> 양현수_53778 | F19: 산업체특강 , 프로젝트 발표(시연), 수료식__12 | L19: [200102]양현수
A20: =IF(B20="","",ROW()-8) -> 12 | B20: 취업특강 및 모의면접 | C20: 8 | D20: =IF(과목12="","",SUM($C$9:$C20)) -> 972 | E20: =IF(L20="","",VLOOKUP(L20,$M$9:$N$12,2,FALSE)) -> 양현수_53778 | F20: 취업특강 및 모의면접__11 | L20: [200102]양현수
A21: =IF(B21="","",ROW()-8) -> 13 | B21: 산업체특강 , 프로젝트 발표(시연), 수료식 | C21: 4 | D21: =IF(과목13="","",SUM($C$9:$C21)) -> 976 | E21: =IF(L21="","",VLOOKUP(L21,$M$9:$N$12,2,FALSE)) -> 양현수_53778 | F21: 산업체특강 , 프로젝트 발표(시연), 수료식__12 | L21: [200102]양현수
A22: =IF(B22="","",ROW()-8) | D22: =IF(과목14="","",SUM($C$9:$C22)) | E22: =IF(L22="","",VLOOKUP(L22,$M$9:$N$12,2,FALSE))
A23: =IF(B23="","",ROW()-8) | D23: =IF(과목15="","",SUM($C$9:$C23)) | E23: =IF(L23="","",VLOOKUP(L23,$M$9:$N$12,2,FALSE))
D24: =IF(과목16="","",SUM($C$9:$C24)) | E24: =IF(L24="","",VLOOKUP(L24,$M$9:$N$12,2,FALSE))
D25: =IF(과목17="","",SUM($C$9:$C25)) | E25: =IF(L25="","",VLOOKUP(L25,$M$9:$N$12,2,FALSE))
D26: =IF(과목18="","",SUM($C$9:$C26)) | E26: =IF(L26="","",VLOOKUP(L26,$M$9:$N$12,2,FALSE))
A27: =IF(B27="","",ROW()-8) | D27: =IF(과목19="","",SUM($C$9:$C27)) | E27: =IF(L27="","",VLOOKUP(L27,$M$9:$N$12,2,FALSE))
A28: =IF(B28="","",ROW()-8) | D28: =IF(과목20="","",SUM($C$9:$C28)) | E28: =IF(L28="","",VLOOKUP(L28,$M$9:$N$12,2,FALSE))
A29: =IF(B29="","",ROW()-8) | D29: =IF(과목21="","",SUM($C$9:$C29)) | E29: =IF(L29="","",VLOOKUP(L29,$M$9:$N$12,2,FALSE))
A30: =IF(B30="","",ROW()-8) | D30: =IF(과목22="","",SUM($C$9:$C30)) | E30: =IF(L30="","",VLOOKUP(L30,$M$9:$N$12,2,FALSE))
A31: =IF(B31="","",ROW()-8) | D31: =IF(과목23="","",SUM($C$9:$C31)) | E31: =IF(L31="","",VLOOKUP(L31,$M$9:$N$12,2,FALSE))
A32: =IF(B32="","",ROW()-8) | D32: =IF(과목24="","",SUM($C$9:$C32)) | E32: =IF(L32="","",VLOOKUP(L32,$M$9:$N$12,2,FALSE))
A33: =IF(B33="","",ROW()-8) | D33: =IF(과목25="","",SUM($C$9:$C33)) | E33: =IF(L33="","",VLOOKUP(L33,$M$9:$N$12,2,FALSE))
C34: =SUM(C9:C33) -> 976

Sheet 세부시간표
A1: 일자별 시간표 내역을 입력합니다 | E1: 교시별 세부 시간표 내역을 입력합니다 | J1: 교과목명 및 능력단위명 | K1: 강의실 | L1: 훈련교사
A2: 훈련일자 | B2: 훈련시작시간 | C2: 훈련종료시간 | D2: 방학/원격여부 | E2: 시작시간 | F2: 시간구분 | G2: 훈련강사코드 | H2: 교육장소(강의실)코드 | I2: 교과목(및 능력단위)코드 | N2: 훈련 시간 | O2: 과목 번호 | Q2: 훈련일차
A3: =TEXT(R3,"yyyymmdd") -> 20250922 | B3: 0900 | C3: 1740 | E3: 0900 | F3: 1 | G3: =IF(OR(N3="",N3>기본입력!$C$34),"",VLOOKUP(O3,기본입력!$A$9:$F$33,5)) -> 양현수_53778 | H3: =IF(OR(N3="",N3>기본입력!$C$34),"",기본입력!$C$6) -> 1교육실(실습겸용강의실)_243089 | I3: =IF(OR(O3="",N3>기본입력!$C$34),"",VLOOKUP(O3,기본입력!$A$9:$F$33,6,FALSE)) -> 웹 애플리케이션 개발__3 | J3: =IF(F3="2","",LEFT(I3,FIND("_",I3,2)-1)) -> 웹 애플리케이션 개발 | K3: =IF(F3="2","",LEFT(H3,FIND("_",H3,2)-1)) -> 1교육실(실습겸용강의실) | L3: =IF(F3="2","",LEFT(G3,FIND("_",G3,2)-1)) -> 양현수 | N3: =IF(F3="2","",COUNTIF($F$3:$F3,"=1")) -> 1 | O3: =IF(F3="2","",IF(N3<=누적시수1,1,IF(N3<=누적시수2,2,IF(N3<=누적시수3,3,IF(N3<=누적시수4,4,IF(N3<=누적시수5,5,IF(N3<=누적시수6,6,IF(N3<=누적시수7,7,IF(N3<=누적시수8,8,IF(N3<=누적시수9,9,IF(N3<=누적시수10,10,IF(N3<=누적시수11,11,IF(N3<=누적시수12,12,IF(N3<=누적시수13,13,IF(N3<=누적시수14,14,IF(N3<=누적시수15,15,IF(N3<=누적시수16,16,IF(N3<=누적시수17,17,IF(N3<=누적시수18,18,IF(N3<=누적시수19,19,IF(N3<=누적시수20,20,IF(N3<=누적시수21,21,IF(N3<=누적시수22,22,IF(N3<=누적시수23,23,IF(N3<=누적시수24,24,IF(N3<=누적시수25,25,0)))))))))))))))))))))))))) -> 1 | P3: =MOD(ROW(),9) -> 3 | Q3: =COUNTIF($P$3:P3,"=3") -> 1 | R3: =WORKDAY(기본입력!$H$2,Q3-1,공휴일) -> 45922
A4: =TEXT(R4,"yyyymmdd") -> 20250922 | B4: 0900 | C4: 1740 | E4: 1000 | F4: 1 | G4: =IF(OR(N4="",N4>기본입력!$C$34),"",VLOOKUP(O4,기본입력!$A$9:$F$33,5)) -> 양현수_53778 | H4: =IF(OR(N4="",N4>기본입력!$C$34),"",기본입력!$C$6) -> 1교육실(실습겸용강의실)_243089 | I4: =IF(OR(O4="",N4>기본입력!$C$34),"",VLOOKUP(O4,기본입력!$A$9:$F$33,6,FALSE)) -> 웹 애플리케이션 개발__3 | J4: =IF(F4="2","",LEFT(I4,FIND("_",I4,2)-1)) -> 웹 애플리케이션 개발 | K4: =IF(F4="2","",LEFT(H4,FIND("_",H4,2)-1)) -> 1교육실(실습겸용강의실) | L4: =IF(F4="2","",LEFT(G4,FIND("_",G4,2)-1)) -> 양현수 | N4: =IF(F4="2","",COUNTIF($F$3:$F4,"=1")) -> 2 | O4: =IF(F4="2","",IF(N4<=누적시수1,1,IF(N4<=누적시수2,2,IF(N4<=누적시수3,3,IF(N4<=누적시수4,4,IF(N4<=누적시수5,5,IF(N4<=누적시수6,6,IF(N4<=누적시수7,7,IF(N4<=누적시수8,8,IF(N4<=누적시수9,9,IF(N4<=누적시수10,10,IF(N4<=누적시수11,11,IF(N4<=누적시수12,12,IF(N4<=누적시수13,13,IF(N4<=누적시수14,14,IF(N4<=누적시수15,15,IF(N4<=누적시수16,16,IF(N4<=누적시수17,17,IF(N4<=누적시수18,18,IF(N4<=누적시수19,19,IF(N4<=누적시수20,20,IF(N4<=누적시수21,21,IF(N4<=누적시수22,22,IF(N4<=누적시수23,23,IF(N4<=누적시수24,24,IF(N4<=누적시수25,25,0)))))))))))))))))))))))))) -> 1 | P4: =MOD(ROW(),9) -> 4 | Q4: =COUNTIF($P$3:P4,"=3") -> 1 | R4: =WORKDAY(기본입력!$H$2,Q4-1,공휴일) -> 45922
A5: =TEXT(R5,"yyyymmdd") -> 20250922 | B5: 0900 | C5: 1740 | E5: 1100 | F5: 1 | G5: =IF(OR(N5="",N5>기본입력!$C$34),"",VLOOKUP(O5,기본입력!$A$9:$F$33,5)) -> 양현수_53778 | H5: =IF(OR(N5="",N5>기본입력!$C$34),"",기본입력!$C$6) -> 1교육실(실습겸용강의실)_243089 | I5: =IF(OR(O5="",N5>기본입력!$C$34),"",VLOOKUP(O5,기본입력!$A$9:$F$33,6,FALSE)) -> 웹 애플리케이션 개발__3 | J5: =IF(F5="2","",LEFT(I5,FIND("_",I5,2)-1)) -> 웹 애플리케이션 개발 | K5: =IF(F5="2","",LEFT(H5,FIND("_",H5,2)-1)) -> 1교육실(실습겸용강의실) | L5: =IF(F5="2","",LEFT(G5,FIND("_",G5,2)-1)) -> 양현수 | N5: =IF(F5="2","",COUNTIF($F$3:$F5,"=1")) -> 3 | O5: =IF(F5="2","",IF(N5<=누적시수1,1,IF(N5<=누적시수2,2,IF(N5<=누적시수3,3,IF(N5<=누적시수4,4,IF(N5<=누적시수5,5,IF(N5<=누적시수6,6,IF(N5<=누적시수7,7,IF(N5<=누적시수8,8,IF(N5<=누적시수9,9,IF(N5<=누적시수10,10,IF(N5<=누적시수11,11,IF(N5<=누적시수12,12,IF(N5<=누적시수13,13,IF(N5<=누적시수14,14,IF(N5<=누적시수15,15,IF(N5<=누적시수16,16,IF(N5<=누적시수17,17,IF(N5<=누적시수18,18,IF(N5<=누적시수19,19,IF(N5<=누적시수20,20,IF(N5<=누적시수21,21,IF(N5<=누적시수22,22,IF(N5<=누적시수23,23,IF(N5<=누적시수24,24,IF(N5<=누적시수25,25,0)))))))))))))))))))))))))) -> 1 | P5: =MOD(ROW(),9) -> 5 | Q5: =COUNTIF($P$3:P5,"=3") -> 1 | R5: =WORKDAY(기본입력!$H$2,Q5-1,공휴일) -> 45922
A6: =TEXT(R6,"yyyymmdd") -> 20250922 | B6: 0900 | C6: 1740 | E6: 1200 | F6: 1 | G6: =IF(OR(N6="",N6>기본입력!$C$34),"",VLOOKUP(O6,기본입력!$A$9:$F$33,5)) -> 양현수_53778 | H6: =IF(OR(N6="",N6>기본입력!$C$34),"",기본입력!$C$6) -> 1교육실(실습겸용강의실)_243089 | I6: =IF(OR(O6="",N6>기본입력!$C$34),"",VLOOKUP(O6,기본입력!$A$9:$F$33,6,FALSE)) -> 웹 애플리케이션 개발__3 | J6: =IF(F6="2","",LEFT(I6,FIND("_",I6,2)-1)) -> 웹 애플리케이션 개발 | K6: =IF(F6="2","",LEFT(H6,FIND("_",H6,2)-1)) -> 1교육실(실습겸용강의실) | L6: =IF(F6="2","",LEFT(G6,FIND("_",G6,2)-1)) -> 양현수 | N6: =IF(F6="2","",COUNTIF($F$3:$F6,"=1")) -> 4 | O6: =IF(F6="2","",IF(N6<=누적시수1,1,IF(N6<=누적시수2,2,IF(N6<=누적시수3,3,IF(N6<=누적시수4,4,IF(N6<=누적시수5,5,IF(N6<=누적시수6,6,IF(N6<=누적시수7,7,IF(N6<=누적시수8,8,IF(N6<=누적시수9,9,IF(N6<=누적시수10,10,IF(N6<=누적시수11,11,IF(N6<=누적시수12,12,IF(N6<=누적시수13,13,IF(N6<=누적시수14,14,IF(N6<=누적시수15,15,IF(N6<=누적시수16,16,IF(N6<=누적시수17,17,IF(N6<=누적시수18,18,IF(N6<=누적시수19,19,IF(N6<=누적시수20,20,IF(N6<=누적시수21,21,IF(N6<=누적시수22,22,IF(N6<=누적시수23,23,IF(N6<=누적시수24,24,IF(N6<=누적시수25,25,0)))))))))))))))))))))))))) -> 1 | P6: =MOD(ROW(),9) -> 6 | Q6: =COUNTIF($P$3:P6,"=3") -> 1 | R6: =WORKDAY(기본입력!$H$2,Q6-1,공휴일) -> 45922
A7: =TEXT(R7,"yyyymmdd") -> 20250922 | B7: 0900 | C7: 1740 | E7: 1300 | F7: 2 | G7: =IF(OR(N7="",N7>기본입력!$C$34),"",VLOOKUP(O7,기본입력!$A$9:$F$33,5)) | H7: =IF(OR(N7="",N7>기본입력!$C$34),"",기본입력!$C$6) | I7: =IF(OR(O7="",N7>기본입력!$C$34),"",VLOOKUP(O7,기본입력!$A$9:$F$33,6,FALSE)) | J7: =IF(F7="2","",LEFT(I7,FIND("_",I7,2)-1)) | K7: =IF(F7="2","",LEFT(H7,FIND("_",H7,2)-1)) | L7: =IF(F7="2","",LEFT(G7,FIND("_",G7,2)-1)) | N7: =IF(F7="2","",COUNTIF($F$3:$F7,"=1")) | O7: =IF(F7="2","",IF(N7<=누적시수1,1,IF(N7<=누적시수2,2,IF(N7<=누적시수3,3,IF(N7<=누적시수4,4,IF(N7<=누적시수5,5,IF(N7<=누적시수6,6,IF(N7<=누적시수7,7,IF(N7<=누적시수8,8,IF(N7<=누적시수9,9,IF(N7<=누적시수10,10,IF(N7<=누적시수11,11,IF(N7<=누적시수12,12,IF(N7<=누적시수13,13,IF(N7<=누적시수14,14,IF(N7<=누적시수15,15,IF(N7<=누적시수16,16,IF(N7<=누적시수17,17,IF(N7<=누적시수18,18,IF(N7<=누적시수19,19,IF(N7<=누적시수20,20,IF(N7<=누적시수21,21,IF(N7<=누적시수22,22,IF(N7<=누적시수23,23,IF(N7<=누적시수24,24,IF(N7<=누적시수25,25,0)))))))))))))))))))))))))) | P7: =MOD(ROW(),9) -> 7 | Q7: =COUNTIF($P$3:P7,"=3") -> 1 | R7: =WORKDAY(기본입력!$H$2,Q7-1,공휴일) -> 45922
A8: =TEXT(R8,"yyyymmdd") -> 20250922 | B8: 0900 | C8: 1740 | E8: 1340 | F8: 1 | G8: =IF(OR(N8="",N8>기본입력!$C$34),"",VLOOKUP(O8,기본입력!$A$9:$F$33,5)) -> 양현수_53778 | H8: =IF(OR(N8="",N8>기본입력!$C$34),"",기본입력!$C$6) -> 1교육실(실습겸용강의실)_243089 | I8: =IF(OR(O8="",N8>기본입력!$C$34),"",VLOOKUP(O8,기본입력!$A$9:$F$33,6,FALSE)) -> 웹 애플리케이션 개발__3 | J8: =IF(F8="2","",LEFT(I8,FIND("_",I8,2)-1)) -> 웹 애플리케이션 개발 | K8: =IF(F8="2","",LEFT(H8,FIND("_",H8,2)-1)) -> 1교육실(실습겸용강의실) | L8: =IF(F8="2","",LEFT(G8,FIND("_",G8,2)-1)) -> 양현수 | N8: =IF(F8="2","",COUNTIF($F$3:$F8,"=1")) -> 5 | O8: =IF(F8="2","",IF(N8<=누적시수1,1,IF(N8<=누적시수2,2,IF(N8<=누적시수3,3,IF(N8<=누적시수4,4,IF(N8<=누적시수5,5,IF(N8<=누적시수6,6,IF(N8<=누적시수7,7,IF(N8<=누적시수8,8,IF(N8<=누적시수9,9,IF(N8<=누적시수10,10,IF(N8<=누적시수11,11,IF(N8<=누적시수12,12,IF(N8<=누적시수13,13,IF(N8<=누적시수14,14,IF(N8<=누적시수15,15,IF(N8<=누적시수16,16,IF(N8<=누적시수17,17,IF(N8<=누적시수18,18,IF(N8<=누적시수19,19,IF(N8<=누적시수20,20,IF(N8<=누적시수21,21,IF(N8<=누적시수22,22,IF(N8<=누적시수23,23,IF(N8<=누적시수24,24,IF(N8<=누적시수25,25,0)))))))))))))))))))))))))) -> 1 | P8: =MOD(ROW(),9) -> 8 | Q8: =COUNTIF($P$3:P8,"=3") -> 1 | R8: =WORKDAY(기본입력!$H$2,Q8-1,공휴일) -> 45922
A9: =TEXT(R9,"yyyymmdd") -> 20250922 | B9: 0900 | C9: 1740 | E9: 1440 | F9: 1 | G9: =IF(OR(N9="",N9>기본입력!$C$34),"",VLOOKUP(O9,기본입력!$A$9:$F$33,5)) -> 양현수_53778 | H9: =IF(OR(N9="",N9>기본입력!$C$34),"",기본입력!$C$6) -> 1교육실(실습겸용강의실)_243089 | I9: =IF(OR(O9="",N9>기본입력!$C$34),"",VLOOKUP(O9,기본입력!$A$9:$F$33,6,FALSE)) -> 웹 애플리케이션 개발__3 | J9: =IF(F9="2","",LEFT(I9,FIND("_",I9,2)-1)) -> 웹 애플리케이션 개발 | K9: =IF(F9="2","",LEFT(H9,FIND("_",H9,2)-1)) -> 1교육실(실습겸용강의실) | L9: =IF(F9="2","",LEFT(G9,FIND("_",G9,2)-1)) -> 양현수 | N9: =IF(F9="2","",COUNTIF($F$3:$F9,"=1")) -> 6 | O9: =IF(F9="2","",IF(N9<=누적시수1,1,IF(N9<=누적시수2,2,IF(N9<=누적시수3,3,IF(N9<=누적시수4,4,IF(N9<=누적시수5,5,IF(N9<=누적시수6,6,IF(N9<=누적시수7,7,IF(N9<=누적시수8,8,IF(N9<=누적시수9,9,IF(N9<=누적시수10,10,IF(N9<=누적시수11,11,IF(N9<=누적시수12,12,IF(N9<=누적시수13,13,IF(N9<=누적시수14,14,IF(N9<=누적시수15,15,IF(N9<=누적시수16,16,IF(N9<=누적시수17,17,IF(N9<=누적시수18,18,IF(N9<=누적시수19,19,IF(N9<=누적시수20,20,IF(N9<=누적시수21,21,IF(N9<=누적시수22,22,IF(N9<=누적시수23,23,IF(N9<=누적시수24,24,IF(N9<=누적시수25,25,0)))))))))))))))))))))))))) -> 1 | P9: =MOD(ROW(),9) -> 0 | Q9: =COUNTIF($P$3:P9,"=3") -> 1 | R9: =WORKDAY(기본입력!$H$2,Q9-1,공휴일) -> 45922
A10: =TEXT(R10,"yyyymmdd") -> 20250922 | B10: 0900 | C10: 1740 | E10: 1540 | F10: 1 | G10: =IF(OR(N10="",N10>기본입력!$C$34),"",VLOOKUP(O10,기본입력!$A$9:$F$33,5)) -> 양현수_53778 | H10: =IF(OR(N10="",N10>기본입력!$C$34),"",기본입력!$C$6) -> 1교육실(실습겸용강의실)_243089 | I10: =IF(OR(O10="",N10>기본입력!$C$34),"",VLOOKUP(O10,기본입력!$A$9:$F$33,6,FALSE)) -> 웹 애플리케이션 개발__3 | J10: =IF(F10="2","",LEFT(I10,FIND("_",I10,2)-1)) -> 웹 애플리케이션 개발 | K10: =IF(F10="2","",LEFT(H10,FIND("_",H10,2)-1)) -> 1교육실(실습겸용강의실) | L10: =IF(F10="2","",LEFT(G10,FIND("_",G10,2)-1)) -> 양현수 | N10: =IF(F10="2","",COUNTIF($F$3:$F10,"=1")) -> 7 | O10: =IF(F10="2","",IF(N10<=누적시수1,1,IF(N10<=누적시수2,2,IF(N10<=누적시수3,3,IF(N10<=누적시수4,4,IF(N10<=누적시수5,5,IF(N10<=누적시수6,6,IF(N10<=누적시수7,7,IF(N10<=누적시수8,8,IF(N10<=누적시수9,9,IF(N10<=누적시수10,10,IF(N10<=누적시수11,11,IF(N10<=누적시수12,12,IF(N10<=누적시수13,13,IF(N10<=누적시수14,14,IF(N10<=누적시수15,15,IF(N10<=누적시수16,16,IF(N10<=누적시수17,17,IF(N10<=누적시수18,18,IF(N10<=누적시수19,19,IF(N10<=누적시수20,20,IF(N10<=누적시수21,21,IF(N10<=누적시수22,22,IF(N10<=누적시수23,23,IF(N10<=누적시수24,24,IF(N10<=누적시수25,25,0)))))))))))))))))))))))))) -> 1 | P10: =MOD(ROW(),9) -> 1 | Q10: =COUNTIF($P$3:P10,"=3") -> 1 | R10: =WORKDAY(기본입력!$H$2,Q10-1,공휴일) -> 45922
A11: =TEXT(R11,"yyyymmdd") -> 20250922 | B11: 0900 | C11: 1740 | E11: 1640 | F11: 1 | G11: =IF(OR(N11="",N11>기본입력!$C$34),"",VLOOKUP(O11,기본입력!$A$9:$F$33,5)) -> 양현수_53778 | H11: =IF(OR(N11="",N11>기본입력!$C$34),"",기본입력!$C$6) -> 1교육실(실습겸용강의실)_243089 | I11: =IF(OR(O11="",N11>기본입력!$C$34),"",VLOOKUP(O11,기본입력!$A$9:$F$33,6,FALSE)) -> 웹 애플리케이션 개발__3 | J11: =IF(F11="2","",LEFT(I11,FIND("_",I11,2)-1)) -> 웹 애플리케이션 개발 | K11: =IF(F11="2","",LEFT(H11,FIND("_",H11,2)-1)) -> 1교육실(실습겸용강의실) | L11: =IF(F11="2","",LEFT(G11,FIND("_",G11,2)-1)) -> 양현수 | N11: =IF(F11="2","",COUNTIF($F$3:$F11,"=1")) -> 8 | O11: =IF(F11="2","",IF(N11<=누적시수1,1,IF(N11<=누적시수2,2,IF(N11<=누적시수3,3,IF(N11<=누적시수4,4,IF(N11<=누적시수5,5,IF(N11<=누적시수6,6,IF(N11<=누적시수7,7,IF(N11<=누적시수8,8,IF(N11<=누적시수9,9,IF(N11<=누적시수10,10,IF(N11<=누적시수11,11,IF(N11<=누적시수12,12,IF(N11<=누적시수13,13,IF(N11<=누적시수14,14,IF(N11<=누적시수15,15,IF(N11<=누적시수16,16,IF(N11<=누적시수17,17,IF(N11<=누적시수18,18,IF(N11<=누적시수19,19,IF(N11<=누적시수20,20,IF(N11<=누적시수21,21,IF(N11<=누적시수22,22,IF(N11<=누적시수23,23,IF(N11<=누적시수24,24,IF(N11<=누적시수25,25,0)))))))))))))))))))))))))) -> 1 | P11: =MOD(ROW(),9) -> 2 | Q11: =COUNTIF($P$3:P11,"=3") -> 1 | R11: =WORKDAY(기본입력!$H$2,Q11-1,공휴일) -> 45922
A12: =TEXT(R12,"yyyymmdd") -> 20250923 | B12: 0900 | C12: 1740 | E12: 0900 | F12: 1 | G12: =IF(OR(N12="",N12>기본입력!$C$34),"",VLOOKUP(O12,기본입력!$A$9:$F$33,5)) -> 양현수_53778 | H12: =IF(OR(N12="",N12>기본입력!$C$34),"",기본입력!$C$6) -> 1교육실(실습겸용강의실)_243089 | I12: =IF(OR(O12="",N12>기본입력!$C$34),"",VLOOKUP(O12,기본입력!$A$9:$F$33,6,FALSE)) -> 웹 애플리케이션 개발__3 | J12: =IF(F12="2","",LEFT(I12,FIND("_",I12,2)-1)) -> 웹 애플리케이션 개발 | K12: =IF(F12="2","",LEFT(H12,FIND("_",H12,2)-1)) -> 1교육실(실습겸용강의실) | L12: =IF(F12="2","",LEFT(G12,FIND("_",G12,2)-1)) -> 양현수 | N12: =IF(F12="2","",COUNTIF($F$3:$F12,"=1")) -> 9 | O12: =IF(F12="2","",IF(N12<=누적시수1,1,IF(N12<=누적시수2,2,IF(N12<=누적시수3,3,IF(N12<=누적시수4,4,IF(N12<=누적시수5,5,IF(N12<=누적시수6,6,IF(N12<=누적시수7,7,IF(N12<=누적시수8,8,IF(N12<=누적시수9,9,IF(N12<=누적시수10,10,IF(N12<=누적시수11,11,IF(N12<=누적시수12,12,IF(N12<=누적시수13,13,IF(N12<=누적시수14,14,IF(N12<=누적시수15,15,IF(N12<=누적시수16,16,IF(N12<=누적시수17,17,IF(N12<=누적시수18,18,IF(N12<=누적시수19,19,IF(N12<=누적시수20,20,IF(N12<=누적시수21,21,IF(N12<=누적시수22,22,IF(N12<=누적시수23,23,IF(N12<=누적시수24,24,IF(N12<=누적시수25,25,0)))))))))))))))))))))))))) -> 1 | P12: =MOD(ROW(),9) -> 3 | Q12: =COUNTIF($P$3:P12,"=3") -> 2 | R12: =WORKDAY(기본입력!$H$2,Q12-1,공휴일) -> 45923
A13: =TEXT(R13,"yyyymmdd") -> 20250923 | B13: 0900 | C13: 1740 | E13: 1000 | F13: 1 | G13: =IF(OR(N13="",N13>기본입력!$C$34),"",VLOOKUP(O13,기본입력!$A$9:$F$33,5)) -> 양현수_53778 | H13: =IF(OR(N13="",N13>기본입력!$C$34),"",기본입력!$C$6) -> 1교육실(실습겸용강의실)_243089 | I13: =IF(OR(O13="",N13>기본입력!$C$34),"",VLOOKUP(O13,기본입력!$A$9:$F$33,6,FALSE)) -> 웹 애플리케이션 개발__3 | J13: =IF(F13="2","",LEFT(I13,FIND("_",I13,2)-1)) -> 웹 애플리케이션 개발 | K13: =IF(F13="2","",LEFT(H13,FIND("_",H13,2)-1)) -> 1교육실(실습겸용강의실) | L13: =IF(F13="2","",LEFT(G13,FIND("_",G13,2)-1)) -> 양현수 | N13: =IF(F13="2","",COUNTIF($F$3:$F13,"=1")) -> 10 | O13: =IF(F13="2","",IF(N13<=누적시수1,1,IF(N13<=누적시수2,2,IF(N13<=누적시수3,3,IF(N13<=누적시수4,4,IF(N13<=누적시수5,5,IF(N13<=누적시수6,6,IF(N13<=누적시수7,7,IF(N13<=누적시수8,8,IF(N13<=누적시수9,9,IF(N13<=누적시수10,10,IF(N13<=누적시수11,11,IF(N13<=누적시수12,12,IF(N13<=누적시수13,13,IF(N13<=누적시수14,14,IF(N13<=누적시수15,15,IF(N13<=누적시수16,16,IF(N13<=누적시수17,17,IF(N13<=누적시수18,18,IF(N13<=누적시수19,19,IF(N13<=누적시수20,20,IF(N13<=누적시수21,21,IF(N13<=누적시수22,22,IF(N13<=누적시수23,23,IF(N13<=누적시수24,24,IF(N13<=누적시수25,25,0)))))))))))))))))))))))))) -> 1 | P13: =MOD(ROW(),9) -> 4 | Q13: =COUNTIF($P$3:P13,"=3") -> 2 | R13: =WORKDAY(기본입력!$H$2,Q13-1,공휴일) -> 45923
A14: =TEXT(R14,"yyyymmdd") -> 20250923 | B14: 0900 | C14: 1740 | E14: 1100 | F14: 1 | G14: =IF(OR(N14="",N14>기본입력!$C$34),"",VLOOKUP(O14,기본입력!$A$9:$F$33,5)) -> 양현수_53778 | H14: =IF(OR(N14="",N14>기본입력!$C$34),"",기본입력!$C$6) -> 1교육실(실습겸용강의실)_243089 | I14: =IF(OR(O14="",N14>기본입력!$C$34),"",VLOOKUP(O14,기본입력!$A$9:$F$33,6,FALSE)) -> 웹 애플리케이션 개발__3 | J14: =IF(F14="2","",LEFT(I14,FIND("_",I14,2)-1)) -> 웹 애플리케이션 개발 | K14: =IF(F14="2","",LEFT(H14,FIND("_",H14,2)-1)) -> 1교육실(실습겸용강의실) | L14: =IF(F14="2","",LEFT(G14,FIND("_",G14,2)-1)) -> 양현수 | N14: =IF(F14="2","",COUNTIF($F$3:$F14,"=1")) -> 11 | O14: =IF(F14="2","",IF(N14<=누적시수1,1,IF(N14<=누적시수2,2,IF(N14<=누적시수3,3,IF(N14<=누적시수4,4,IF(N14<=누적시수5,5,IF(N14<=누적시수6,6,IF(N14<=누적시수7,7,IF(N14<=누적시수8,8,IF(N14<=누적시수9,9,IF(N14<=누적시수10,10,IF(N14<=누적시수11,11,IF(N14<=누적시수12,12,IF(N14<=누적시수13,13,IF(N14<=누적시수14,14,IF(N14<=누적시수15,15,IF(N14<=누적시수16,16,IF(N14<=누적시수17,17,IF(N14<=누적시수18,18,IF(N14<=누적시수19,19,IF(N14<=누적시수20,20,IF(N14<=누적시수21,21,IF(N14<=누적시수22,22,IF(N14<=누적시수23,23,IF(N14<=누적시수24,24,IF(N14<=누적시수25,25,0)))))))))))))))))))))))))) -> 1 | P14: =MOD(ROW(),9) -> 5 | Q14: =COUNTIF($P$3:P14,"=3") -> 2 | R14: =WORKDAY(기본입력!$H$2,Q14-1,공휴일) -> 45923
A15: =TEXT(R15,"yyyymmdd") -> 20250923 | B15: 0900 | C15: 1740 | E15: 1200 | F15: 1 | G15: =IF(OR(N15="",N15>기본입력!$C$34),"",VLOOKUP(O15,기본입력!$A$9:$F$33,5)) -> 양현수_53778 | H15: =IF(OR(N15="",N15>기본입력!$C$34),"",기본입력!$C$6) -> 1교육실(실습겸용강의실)_243089 | I15: =IF(OR(O15="",N15>기본입력!$C$34),"",VLOOKUP(O15,기본입력!$A$9:$F$33,6,FALSE)) -> 웹 애플리케이션 개발__3 | J15: =IF(F15="2","",LEFT(I15,FIND("_",I15,2)-1)) -> 웹 애플리케이션 개발 | K15: =IF(F15="2","",LEFT(H15,FIND("_",H15,2)-1)) -> 1교육실(실습겸용강의실) | L15: =IF(F15="2","",LEFT(G15,FIND("_",G15,2)-1)) -> 양현수 | N15: =IF(F15="2","",COUNTIF($F$3:$F15,"=1")) -> 12 | O15: =IF(F15="2","",IF(N15<=누적시수1,1,IF(N15<=누적시수2,2,IF(N15<=누적시수3,3,IF(N15<=누적시수4,4,IF(N15<=누적시수5,5,IF(N15<=누적시수6,6,IF(N15<=누적시수7,7,IF(N15<=누적시수8,8,IF(N15<=누적시수9,9,IF(N15<=누적시수10,10,IF(N15<=누적시수11,11,IF(N15<=누적시수12,12,IF(N15<=누적시수13,13,IF(N15<=누적시수14,14,IF(N15<=누적시수15,15,IF(N15<=누적시수16,16,IF(N15<=누적시수17,17,IF(N15<=누적시수18,18,IF(N15<=누적시수19,19,IF(N15<=누적시수20,20,IF(N15<=누적시수21,21,IF(N15<=누적시수22,22,IF(N15<=누적시수23,23,IF(N15<=누적시수24,24,IF(N15<=누적시수25,25,0)))))))))))))))))))))))))) -> 1 | P15: =MOD(ROW(),9) -> 6 | Q15: =COUNTIF($P$3:P15,"=3") -> 2 | R15: =WORKDAY(기본입력!$H$2,Q15-1,공휴일) -> 45923
A16: =TEXT(R16,"yyyymmdd") -> 20250923 | B16: 0900 | C16: 1740 | E16: 1300 | F16: 2 | G16: =IF(OR(N16="",N16>기본입력!$C$34),"",VLOOKUP(O16,기본입력!$A$9:$F$33,5)) | H16: =IF(OR(N16="",N16>기본입력!$C$34),"",기본입력!$C$6) | I16: =IF(OR(O16="",N16>기본입력!$C$34),"",VLOOKUP(O16,기본입력!$A$9:$F$33,6,FALSE)) | J16: =IF(F16="2","",LEFT(I16,FIND("_",I16,2)-1)) | K16: =IF(F16="2","",LEFT(H16,FIND("_",H16,2)-1)) | L16: =IF(F16="2","",LEFT(G16,FIND("_",G16,2)-1)) | N16: =IF(F16="2","",COUNTIF($F$3:$F16,"=1")) | O16: =IF(F16="2","",IF(N16<=누적시수1,1,IF(N16<=누적시수2,2,IF(N16<=누적시수3,3,IF(N16<=누적시수4,4,IF(N16<=누적시수5,5,IF(N16<=누적시수6,6,IF(N16<=누적시수7,7,IF(N16<=누적시수8,8,IF(N16<=누적시수9,9,IF(N16<=누적시수10,10,IF(N16<=누적시수11,11,IF(N16<=누적시수12,12,IF(N16<=누적시수13,13,IF(N16<=누적시수14,14,IF(N16<=누적시수15,15,IF(N16<=누적시수16,16,IF(N16<=누적시수17,17,IF(N16<=누적시수18,18,IF(N16<=누적시수19,19,IF(N16<=누적시수20,20,IF(N16<=누적시수21,21,IF(N16<=누적시수22,22,IF(N16<=누적시수23,23,IF(N16<=누적시수24,24,IF(N16<=누적시수25,25,0)))))))))))))))))))))))))) | P16: =MOD(ROW(),9) -> 7 | Q16: =COUNTIF($P$3:P16,"=3") -> 2 | R16: =WORKDAY(기본입력!$H$2,Q16-1,공휴일) -> 45923
A17: =TEXT(R17,"yyyymmdd") -> 20250923 | B17: 0900 | C17: 1740 | E17: 1340 | F17: 1 | G17: =IF(OR(N17="",N17>기본입력!$C$34),"",VLOOKUP(O17,기본입력!$A$9:$F$33,5)) -> 양현수_53778 | H17: =IF(OR(N17="",N17>기본입력!$C$34),"",기본입력!$C$6) -> 1교육실(실습겸용강의실)_243089 | I17: =IF(OR(O17="",N17>기본입력!$C$34),"",VLOOKUP(O17,기본입력!$A$9:$F$33,6,FALSE)) -> 웹 애플리케이션 개발__3 | J17: =IF(F17="2","",LEFT(I17,FIND("_",I17,2)-1)) -> 웹 애플리케이션 개발 | K17: =IF(F17="2","",LEFT(H17,FIND("_",H17,2)-1)) -> 1교육실(실습겸용강의실) | L17: =IF(F17="2","",LEFT(G17,FIND("_",G17,2)-1)) -> 양현수 | N17: =IF(F17="2","",COUNTIF($F$3:$F17,"=1")) -> 13 | O17: =IF(F17="2","",IF(N17<=누적시수1,1,IF(N17<=누적시수2,2,IF(N17<=누적시수3,3,IF(N17<=누적시수4,4,IF(N17<=누적시수5,5,IF(N17<=누적시수6,6,IF(N17<=누적시수7,7,IF(N17<=누적시수8,8,IF(N17<=누적시수9,9,IF(N17<=누적시수10,10,IF(N17<=누적시수11,11,IF(N17<=누적시수12,12,IF(N17<=누적시수13,13,IF(N17<=누적시수14,14,IF(N17<=누적시수15,15,IF(N17<=누적시수16,16,IF(N17<=누적시수17,17,IF(N17<=누적시수18,18,IF(N17<=누적시수19,19,IF(N17<=누적시수20,20,IF(N17<=누적시수21,21,IF(N17<=누적시수22,22,IF(N17<=누적시수23,23,IF(N17<=누적시수24,24,IF(N17<=누적시수25,25,0)))))))))))))))))))))))))) -> 1 | P17: =MOD(ROW(),9) -> 8 | Q17: =COUNTIF($P$3:P17,"=3") -> 2 | R17: =WORKDAY(기본입력!$H$2,Q17-1,공휴일) -> 45923
A18: =TEXT(R18,"yyyymmdd") -> 20250923 | B18: 0900 | C18: 1740 | E18: 1440 | F18: 1 | G18: =IF(OR(N18="",N18>기본입력!$C$34),"",VLOOKUP(O18,기본입력!$A$9:$F$33,5)) -> 양현수_53778 | H18: =IF(OR(N18="",N18>기본입력!$C$34),"",기본입력!$C$6) -> 1교육실(실습겸용강의실)_243089 | I18: =IF(OR(O18="",N18>기본입력!$C$34),"",VLOOKUP(O18,기본입력!$A$9:$F$33,6,FALSE)) -> 웹 애플리케이션 개발__3 | J18: =IF(F18="2","",LEFT(I18,FIND("_",I18,2)-1)) -> 웹 애플리케이션 개발 | K18: =IF(F18="2","",LEFT(H18,FIND("_",H18,2)-1)) -> 1교육실(실습겸용강의실) | L18: =IF(F18="2","",LEFT(G18,FIND("_",G18,2)-1)) -> 양현수 | N18: =IF(F18="2","",COUNTIF($F$3:$F18,"=1")) -> 14 | O18: =IF(F18="2","",IF(N18<=누적시수1,1,IF(N18<=누적시수2,2,IF(N18<=누적시수3,3,IF(N18<=누적시수4,4,IF(N18<=누적시수5,5,IF(N18<=누적시수6,6,IF(N18<=누적시수7,7,IF(N18<=누적시수8,8,IF(N18<=누적시수9,9,IF(N18<=누적시수10,10,IF(N18<=누적시수11,11,IF(N18<=누적시수12,12,IF(N18<=누적시수13,13,IF(N18<=누적시수14,14,IF(N18<=누적시수15,15,IF(N18<=누적시수16,16,IF(N18<=누적시수17,17,IF(N18<=누적시수18,18,IF(N18<=누적시수19,19,IF(N18<=누적시수20,20,IF(N18<=누적시수21,21,IF(N18<=누적시수22,22,IF(N18<=누적시수23,23,IF(N18<=누적시수24,24,IF(N18<=누적시수25,25,0)))))))))))))))))))))))))) -> 1 | P18: =MOD(ROW(),9) -> 0 | Q18: =COUNTIF($P$3:P18,"=3") -> 2 | R18: =WORKDAY(기본입력!$H$2,Q18-1,공휴일) -> 45923
A19: =TEXT(R19,"yyyymmdd") -> 20250923 | B19: 0900 | C19: 1740 | E19: 1540 | F19: 1 | G19: =IF(OR(N19="",N19>기본입력!$C$34),"",VLOOKUP(O19,기본입력!$A$9:$F$33,5)) -> 양현수_53778 | H19: =IF(OR(N19="",N19>기본입력!$C$34),"",기본입력!$C$6) -> 1교육실(실습겸용강의실)_243089 | I19: =IF(OR(O19="",N19>기본입력!$C$34),"",VLOOKUP(O19,기본입력!$A$9:$F$33,6,FALSE)) -> 웹 애플리케이션 개발__3 | J19: =IF(F19="2","",LEFT(I19,FIND("_",I19,2)-1)) -> 웹 애플리케이션 개발 | K19: =IF(F19="2","",LEFT(H19,FIND("_",H19,2)-1)) -> 1교육실(실습겸용강의실) | L19: =IF(F19="2","",LEFT(G19,FIND("_",G19,2)-1)) -> 양현수 | N19: =IF(F19="2","",COUNTIF($F$3:$F19,"=1")) -> 15 | O19: =IF(F19="2","",IF(N19<=누적시수1,1,IF(N19<=누적시수2,2,IF(N19<=누적시수3,3,IF(N19<=누적시수4,4,IF(N19<=누적시수5,5,IF(N19<=누적시수6,6,IF(N19<=누적시수7,7,IF(N19<=누적시수8,8,IF(N19<=누적시수9,9,IF(N19<=누적시수10,10,IF(N19<=누적시수11,11,IF(N19<=누적시수12,12,IF(N19<=누적시수13,13,IF(N19<=누적시수14,14,IF(N19<=누적시수15,15,IF(N19<=누적시수16,16,IF(N19<=누적시수17,17,IF(N19<=누적시수18,18,IF(N19<=누적시수19,19,IF(N19<=누적시수20,20,IF(N19<=누적시수21,21,IF(N19<=누적시수22,22,IF(N19<=누적시수23,23,IF(N19<=누적시수24,24,IF(N19<=누적시수25,25,0)))))))))))))))))))))))))) -> 1 | P19: =MOD(ROW(),9) -> 1 | Q19: =COUNTIF($P$3:P19,"=3") -> 2 | R19: =WORKDAY(기본입력!$H$2,Q19-1,공휴일) -> 45923
A20: =TEXT(R20,"yyyymmdd") -> 20250923 | B20: 0900 | C20: 1740 | E20: 1640 | F20: 1 | G20: =IF(OR(N20="",N20>기본입력!$C$34),"",VLOOKUP(O20,기본입력!$A$9:$F$33,5)) -> 양현수_53778 | H20: =IF(OR(N20="",N20>기본입력!$C$34),"",기본입력!$C$6) -> 1교육실(실습겸용강의실)_243089 | I20: =IF(OR(O20="",N20>기본입력!$C$34),"",VLOOKUP(O20,기본입력!$A$9:$F$33,6,FALSE)) -> 웹 애플리케이션 개발__3 | J20: =IF(F20="2","",LEFT(I20,FIND("_",I20,2)-1)) -> 웹 애플리케이션 개발 | K20: =IF(F20="2","",LEFT(H20,FIND("_",H20,2)-1)) -> 1교육실(실습겸용강의실) | L20: =IF(F20="2","",LEFT(G20,FIND("_",G20,2)-1)) -> 양현수 | N20: =IF(F20="2","",COUNTIF($F$3:$F20,"=1")) -> 16 | O20: =IF(F20="2","",IF(N20<=누적시수1,1,IF(N20<=누적시수2,2,IF(N20<=누적시수3,3,IF(N20<=누적시수4,4,IF(N20<=누적시수5,5,IF(N20<=누적시수6,6,IF(N20<=누적시수7,7,IF(N20<=누적시수8,8,IF(N20<=누적시수9,9,IF(N20<=누적시수10,10,IF(N20<=누적시수11,11,IF(N20<=누적시수12,12,IF(N20<=누적시수13,13,IF(N20<=누적시수14,14,IF(N20<=누적시수15,15,IF(N20<=누적시수16,16,IF(N20<=누적시수17,17,IF(N20<=누적시수18,18,IF(N20<=누적시수19,19,IF(N20<=누적시수20,20,IF(N20<=누적시수21,21,IF(N20<=누적시수22,22,IF(N20<=누적시수23,23,IF(N20<=누적시수24,24,IF(N20<=누적시수25,25,0)))))))))))))))))))))))))) -> 1 | P20: =MOD(ROW(),9) -> 2 | Q20: =COUNTIF($P$3:P20,"=3") -> 2 | R20: =WORKDAY(기본입력!$H$2,Q20-1,공휴일) -> 45923
A21: =TEXT(R21,"yyyymmdd") -> 20250924 | B21: 0900 | C21: 1740 | E21: 0900 | F21: 1 | G21: =IF(OR(N21="",N21>기본입력!$C$34),"",VLOOKUP(O21,기본입력!$A$9:$F$33,5)) -> 양현수_53778 | H21: =IF(OR(N21="",N21>기본입력!$C$34),"",기본입력!$C$6) -> 1교육실(실습겸용강의실)_243089 | I21: =IF(OR(O21="",N21>기본입력!$C$34),"",VLOOKUP(O21,기본입력!$A$9:$F$33,6,FALSE)) -> 웹 애플리케이션 개발__3 | J21: =IF(F21="2","",LEFT(I21,FIND("_",I21,2)-1)) -> 웹 애플리케이션 개발 | K21: =IF(F21="2","",LEFT(H21,FIND("_",H21,2)-1)) -> 1교육실(실습겸용강의실) | L21: =IF(F21="2","",LEFT(G21,FIND("_",G21,2)-1)) -> 양현수 | N21: =IF(F21="2","",COUNTIF($F$3:$F21,"=1")) -> 17 | O21: =IF(F21="2","",IF(N21<=누적시수1,1,IF(N21<=누적시수2,2,IF(N21<=누적시수3,3,IF(N21<=누적시수4,4,IF(N21<=누적시수5,5,IF(N21<=누적시수6,6,IF(N21<=누적시수7,7,IF(N21<=누적시수8,8,IF(N21<=누적시수9,9,IF(N21<=누적시수10,10,IF(N21<=누적시수11,11,IF(N21<=누적시수12,12,IF(N21<=누적시수13,13,IF(N21<=누적시수14,14,IF(N21<=누적시수15,15,IF(N21<=누적시수16,16,IF(N21<=누적시수17,17,IF(N21<=누적시수18,18,IF(N21<=누적시수19,19,IF(N21<=누적시수20,20,IF(N21<=누적시수21,21,IF(N21<=누적시수22,22,IF(N21<=누적시수23,23,IF(N21<=누적시수24,24,IF(N21<=누적시수25,25,0)))))))))))))))))))))))))) -> 1 | P21: =MOD(ROW(),9) -> 3 | Q21: =COUNTIF($P$3:P21,"=3") -> 3 | R21: =WORKDAY(기본입력!$H$2,Q21-1,공휴일) -> 45924
A22: =TEXT(R22,"yyyymmdd") -> 20250924 | B22: 0900 | C22: 1740 | E22: 1000 | F22: 1 | G22: =IF(OR(N22="",N22>기본입력!$C$34),"",VLOOKUP(O22,기본입력!$A$9:$F$33,5)) -> 양현수_53778 | H22: =IF(OR(N22="",N22>기본입력!$C$34),"",기본입력!$C$6) -> 1교육실(실습겸용강의실)_243089 | I22: =IF(OR(O22="",N22>기본입력!$C$34),"",VLOOKUP(O22,기본입력!$A$9:$F$33,6,FALSE)) -> 웹 애플리케이션 개발__3 | J22: =IF(F22="2","",LEFT(I22,FIND("_",I22,2)-1)) -> 웹 애플리케이션 개발 | K22: =IF(F22="2","",LEFT(H22,FIND("_",H22,2)-1)) -> 1교육실(실습겸용강의실) | L22: =IF(F22="2","",LEFT(G22,FIND("_",G22,2)-1)) -> 양현수 | N22: =IF(F22="2","",COUNTIF($F$3:$F22,"=1")) -> 18 | O22: =IF(F22="2","",IF(N22<=누적시수1,1,IF(N22<=누적시수2,2,IF(N22<=누적시수3,3,IF(N22<=누적시수4,4,IF(N22<=누적시수5,5,IF(N22<=누적시수6,6,IF(N22<=누적시수7,7,IF(N22<=누적시수8,8,IF(N22<=누적시수9,9,IF(N22<=누적시수10,10,IF(N22<=누적시수11,11,IF(N22<=누적시수12,12,IF(N22<=누적시수13,13,IF(N22<=누적시수14,14,IF(N22<=누적시수15,15,IF(N22<=누적시수16,16,IF(N22<=누적시수17,17,IF(N22<=누적시수18,18,IF(N22<=누적시수19,19,IF(N22<=누적시수20,20,IF(N22<=누적시수21,21,IF(N22<=누적시수22,22,IF(N22<=누적시수23,23,IF(N22<=누적시수24,24,IF(N22<=누적시수25,25,0)))))))))))))))))))))))))) -> 1 | P22: =MOD(ROW(),9) -> 4 | Q22: =COUNTIF($P$3:P22,"=3") -> 3 | R22: =WORKDAY(기본입력!$H$2,Q22-1,공휴일) -> 45924
A23: =TEXT(R23,"yyyymmdd") -> 20250924 | B23: 0900 | C23: 1740 | E23: 1100 | F23: 1 | G23: =IF(OR(N23="",N23>기본입력!$C$34),"",VLOOKUP(O23,기본입력!$A$9:$F$33,5)) -> 양현수_53778 | H23: =IF(OR(N23="",N23>기본입력!$C$34),"",기본입력!$C$6) -> 1교육실(실습겸용강의실)_243089 | I23: =IF(OR(O23="",N23>기본입력!$C$34),"",VLOOKUP(O23,기본입력!$A$9:$F$33,6,FALSE)) -> 웹 애플리케이션 개발__3 | J23: =IF(F23="2","",LEFT(I23,FIND("_",I23,2)-1)) -> 웹 애플리케이션 개발 | K23: =IF(F23="2","",LEFT(H23,FIND("_",H23,2)-1)) -> 1교육실(실습겸용강의실) | L23: =IF(F23="2","",LEFT(G23,FIND("_",G23,2)-1)) -> 양현수 | N23: =IF(F23="2","",COUNTIF($F$3:$F23,"=1")) -> 19 | O23: =IF(F23="2","",IF(N23<=누적시수1,1,IF(N23<=누적시수2,2,IF(N23<=누적시수3,3,IF(N23<=누적시수4,4,IF(N23<=누적시수5,5,IF(N23<=누적시수6,6,IF(N23<=누적시수7,7,IF(N23<=누적시수8,8,IF(N23<=누적시수9,9,IF(N23<=누적시수10,10,IF(N23<=누적시수11,11,IF(N23<=누적시수12,12,IF(N23<=누적시수13,13,IF(N23<=누적시수14,14,IF(N23<=누적시수15,15,IF(N23<=누적시수16,16,IF(N23<=누적시수17,17,IF(N23<=누적시수18,18,IF(N23<=누적시수19,19,IF(N23<=누적시수20,20,IF(N23<=누적시수21,21,IF(N23<=누적시수22,22,IF(N23<=누적시수23,23,IF(N23<=누적시수24,24,IF(N23<=누적시수25,25,0)))))))))))))))))))))))))) -> 1 | P23: =MOD(ROW(),9) -> 5 | Q23: =COUNTIF($P$3:P23,"=3") -> 3 | R23: =WORKDAY(기본입력!$H$2,Q23-1,공휴일) -> 45924
A24: =TEXT(R24,"yyyymmdd") -> 20250924 | B24: 0900 | C24: 1740 | E24: 1200 | F24: 1 | G24: =IF(OR(N24="",N24>기본입력!$C$34),"",VLOOKUP(O24,기본입력!$A$9:$F$33,5)) -> 양현수_53778 | H24: =IF(OR(N24="",N24>기본입력!$C$34),"",기본입력!$C$6) -> 1교육실(실습겸용강의실)_243089 | I24: =IF(OR(O24="",N24>기본입력!$C$34),"",VLOOKUP(O24,기본입력!$A$9:$F$33,6,FALSE)) -> 웹 애플리케이션 개발__3 | J24: =IF(F24="2","",LEFT(I24,FIND("_",I24,2)-1)) -> 웹 애플리케이션 개발 | K24: =IF(F24="2","",LEFT(H24,FIND("_",H24,2)-1)) -> 1교육실(실습겸용강의실) | L24: =IF(F24="2","",LEFT(G24,FIND("_",G24,2)-1)) -> 양현수 | N24: =IF(F24="2","",COUNTIF($F$3:$F24,"=1")) -> 20 | O24: =IF(F24="2","",IF(N24<=누적시수1,1,IF(N24<=누적시수2,2,IF(N24<=누적시수3,3,IF(N24<=누적시수4,4,IF(N24<=누적시수5,5,IF(N24<=누적시수6,6,IF(N24<=누적시수7,7,IF(N24<=누적시수8,8,IF(N24<=누적시수9,9,IF(N24<=누적시수10,10,IF(N24<=누적시수11,11,IF(N24<=누적시수12,12,IF(N24<=누적시수13,13,IF(N24<=누적시수14,14,IF(N24<=누적시수15,15,IF(N24<=누적시수16,16,IF(N24<=누적시수17,17,IF(N24<=누적시수18,18,IF(N24<=누적시수19,19,IF(N24<=누적시수20,20,IF(N24<=누적시수21,21,IF(N24<=누적시수22,22,IF(N24<=누적시수23,23,IF(N24<=누적시수24,24,IF(N24<=누적시수25,25,0)))))))))))))))))))))))))) -> 1 | P24: =MOD(ROW(),9) -> 6 | Q24: =COUNTIF($P$3:P24,"=3") -> 3 | R24: =WORKDAY(기본입력!$H$2,Q24-1,공휴일) -> 45924
A25: =TEXT(R25,"yyyymmdd") -> 20250924 | B25: 0900 | C25: 1740 | E25: 1300 | F25: 2 | G25: =IF(OR(N25="",N25>기본입력!$C$34),"",VLOOKUP(O25,기본입력!$A$9:$F$33,5)) | H25: =IF(OR(N25="",N25>기본입력!$C$34),"",기본입력!$C$6) | I25: =IF(OR(O25="",N25>기본입력!$C$34),"",VLOOKUP(O25,기본입력!$A$9:$F$33,6,FALSE)) | J25: =IF(F25="2","",LEFT(I25,FIND("_",I25,2)-1)) | K25: =IF(F25="2","",LEFT(H25,FIND("_",H25,2)-1)) | L25: =IF(F25="2","",LEFT(G25,FIND("_",G25,2)-1)) | N25: =IF(F25="2","",COUNTIF($F$3:$F25,"=1")) | O25: =IF(F25="2","",IF(N25<=누적시수1,1,IF(N25<=누적시수2,2,IF(N25<=누적시수3,3,IF(N25<=누적시수4,4,IF(N25<=누적시수5,5,IF(N25<=누적시수6,6,IF(N25<=누적시수7,7,IF(N25<=누적시수8,8,IF(N25<=누적시수9,9,IF(N25<=누적시수10,10,IF(N25<=누적시수11,11,IF(N25<=누적시수12,12,IF(N25<=누적시수13,13,IF(N25<=누적시수14,14,IF(N25<=누적시수15,15,IF(N25<=누적시수16,16,IF(N25<=누적시수17,17,IF(N25<=누적시수18,18,IF(N25<=누적시수19,19,IF(N25<=누적시수20,20,IF(N25<=누적시수21,21,IF(N25<=누적시수22,22,IF(N25<=누적시수23,23,IF(N25<=누적시수24,24,IF(N25<=누적시수25,25,0)))))))))))))))))))))))))) | P25: =MOD(ROW(),9) -> 7 | Q25: =COUNTIF($P$3:P25,"=3") -> 3 | R25: =WORKDAY(기본입력!$H$2,Q25-1,공휴일) -> 45924
A26: =TEXT(R26,"yyyymmdd") -> 20250924 | B26: 0900 | C26: 1740 | E26: 1340 | F26: 1 | G26: =IF(OR(N26="",N26>기본입력!$C$34),"",VLOOKUP(O26,기본입력!$A$9:$F$33,5)) -> 양현수_53778 | H26: =IF(OR(N26="",N26>기본입력!$C$34),"",기본입력!$C$6) -> 1교육실(실습겸용강의실)_243089 | I26: =IF(OR(O26="",N26>기본입력!$C$34),"",VLOOKUP(O26,기본입력!$A$9:$F$33,6,FALSE)) -> 웹 애플리케이션 개발__3 | J26: =IF(F26="2","",LEFT(I26,FIND("_",I26,2)-1)) -> 웹 애플리케이션 개발 | K26: =IF(F26="2","",LEFT(H26,FIND("_",H26,2)-1)) -> 1교육실(실습겸용강의실) | L26: =IF(F26="2","",LEFT(G26,FIND("_",G26,2)-1)) -> 양현수 | N26: =IF(F26="2","",COUNTIF($F$3:$F26,"=1")) -> 21 | O26: =IF(F26="2","",IF(N26<=누적시수1,1,IF(N26<=누적시수2,2,IF(N26<=누적시수3,3,IF(N26<=누적시수4,4,IF(N26<=누적시수5,5,IF(N26<=누적시수6,6,IF(N26<=누적시수7,7,IF(N26<=누적시수8,8,IF(N26<=누적시수9,9,IF(N26<=누적시수10,10,IF(N26<=누적시수11,11,IF(N26<=누적시수12,12,IF(N26<=누적시수13,13,IF(N26<=누적시수14,14,IF(N26<=누적시수15,15,IF(N26<=누적시수16,16,IF(N26<=누적시수17,17,IF(N26<=누적시수18,18,IF(N26<=누적시수19,19,IF(N26<=누적시수20,20,IF(N26<=누적시수21,21,IF(N26<=누적시수22,22,IF(N26<=누적시수23,23,IF(N26<=누적시수24,24,IF(N26<=누적시수25,25,0)))))))))))))))))))))))))) -> 1 | P26: =MOD(ROW(),9) -> 8 | Q26: =COUNTIF($P$3:P26,"=3") -> 3 | R26: =WORKDAY(기본입력!$H$2,Q26-1,공휴일) -> 45924
A27: =TEXT(R27,"yyyymmdd") -> 20250924 | B27: 0900 | C27: 1740 | E27: 1440 | F27: 1 | G27: =IF(OR(N27="",N27>기본입력!$C$34),"",VLOOKUP(O27,기본입력!$A$9:$F$33,5)) -> 양현수_53778 | H27: =IF(OR(N27="",N27>기본입력!$C$34),"",기본입력!$C$6) -> 1교육실(실습겸용강의실)_243089 | I27: =IF(OR(O27="",N27>기본입력!$C$34),"",VLOOKUP(O27,기본입력!$A$9:$F$33,6,FALSE)) -> 웹 애플리케이션 개발__3 | J27: =IF(F27="2","",LEFT(I27,FIND("_",I27,2)-1)) -> 웹 애플리케이션 개발 | K27: =IF(F27="2","",LEFT(H27,FIND("_",H27,2)-1)) -> 1교육실(실습겸용강의실) | L27: =IF(F27="2","",LEFT(G27,FIND("_",G27,2)-1)) -> 양현수 | N27: =IF(F27="2","",COUNTIF($F$3:$F27,"=1")) -> 22 | O27: =IF(F27="2","",IF(N27<=누적시수1,1,IF(N27<=누적시수2,2,IF(N27<=누적시수3,3,IF(N27<=누적시수4,4,IF(N27<=누적시수5,5,IF(N27<=누적시수6,6,IF(N27<=누적시수7,7,IF(N27<=누적시수8,8,IF(N27<=누적시수9,9,IF(N27<=누적시수10,10,IF(N27<=누적시수11,11,IF(N27<=누적시수12,12,IF(N27<=누적시수13,13,IF(N27<=누적시수14,14,IF(N27<=누적시수15,15,IF(N27<=누적시수16,16,IF(N27<=누적시수17,17,IF(N27<=누적시수18,18,IF(N27<=누적시수19,19,IF(N27<=누적시수20,20,IF(N27<=누적시수21,21,IF(N27<=누적시수22,22,IF(N27<=누적시수23,23,IF(N27<=누적시수24,24,IF(N27<=누적시수25,25,0)))))))))))))))))))))))))) -> 1 | P27: =MOD(ROW(),9) -> 0 | Q27: =COUNTIF($P$3:P27,"=3") -> 3 | R27: =WORKDAY(기본입력!$H$2,Q27-1,공휴일) -> 45924
A28: =TEXT(R28,"yyyymmdd") -> 20250924 | B28: 0900 | C28: 1740 | E28: 1540 | F28: 1 | G28: =IF(OR(N28="",N28>기본입력!$C$34),"",VLOOKUP(O28,기본입력!$A$9:$F$33,5)) -> 양현수_53778 | H28: =IF(OR(N28="",N28>기본입력!$C$34),"",기본입력!$C$6) -> 1교육실(실습겸용강의실)_243089 | I28: =IF(OR(O28="",N28>기본입력!$C$34),"",VLOOKUP(O28,기본입력!$A$9:$F$33,6,FALSE)) -> 웹 애플리케이션 개발__3 | J28: =IF(F28="2","",LEFT(I28,FIND("_",I28,2)-1)) -> 웹 애플리케이션 개발 | K28: =IF(F28="2","",LEFT(H28,FIND("_",H28,2)-1)) -> 1교육실(실습겸용강의실) | L28: =IF(F28="2","",LEFT(G28,FIND("_",G28,2)-1)) -> 양현수 | N28: =IF(F28="2","",COUNTIF($F$3:$F28,"=1")) -> 23 | O28: =IF(F28="2","",IF(N28<=누적시수1,1,IF(N28<=누적시수2,2,IF(N28<=누적시수3,3,IF(N28<=누적시수4,4,IF(N28<=누적시수5,5,IF(N28<=누적시수6,6,IF(N28<=누적시수7,7,IF(N28<=누적시수8,8,IF(N28<=누적시수9,9,IF(N28<=누적시수10,10,IF(N28<=누적시수11,11,IF(N28<=누적시수12,12,IF(N28<=누적시수13,13,IF(N28<=누적시수14,14,IF(N28<=누적시수15,15,IF(N28<=누적시수16,16,IF(N28<=누적시수17,17,IF(N28<=누적시수18,18,IF(N28<=누적시수19,19,IF(N28<=누적시수20,20,IF(N28<=누적시수21,21,IF(N28<=누적시수22,22,IF(N28<=누적시수23,23,IF(N28<=누적시수24,24,IF(N28<=누적시수25,25,0)))))))))))))))))))))))))) -> 1 | P28: =MOD(ROW(),9) -> 1 | Q28: =COUNTIF($P$3:P28,"=3") -> 3 | R28: =WORKDAY(기본입력!$H$2,Q28-1,공휴일) -> 45924
A29: =TEXT(R29,"yyyymmdd") -> 20250924 | B29: 0900 | C29: 1740 | E29: 1640 | F29: 1 | G29: =IF(OR(N29="",N29>기본입력!$C$34),"",VLOOKUP(O29,기본입력!$A$9:$F$33,5)) -> 양현수_53778 | H29: =IF(OR(N29="",N29>기본입력!$C$34),"",기본입력!$C$6) -> 1교육실(실습겸용강의실)_243089 | I29: =IF(OR(O29="",N29>기본입력!$C$34),"",VLOOKUP(O29,기본입력!$A$9:$F$33,6,FALSE)) -> 웹 애플리케이션 개발__3 | J29: =IF(F29="2","",LEFT(I29,FIND("_",I29,2)-1)) -> 웹 애플리케이션 개발 | K29: =IF(F29="2","",LEFT(H29,FIND("_",H29,2)-1)) -> 1교육실(실습겸용강의실) | L29: =IF(F29="2","",LEFT(G29,FIND("_",G29,2)-1)) -> 양현수 | N29: =IF(F29="2","",COUNTIF($F$3:$F29,"=1")) -> 24 | O29: =IF(F29="2","",IF(N29<=누적시수1,1,IF(N29<=누적시수2,2,IF(N29<=누적시수3,3,IF(N29<=누적시수4,4,IF(N29<=누적시수5,5,IF(N29<=누적시수6,6,IF(N29<=누적시수7,7,IF(N29<=누적시수8,8,IF(N29<=누적시수9,9,IF(N29<=누적시수10,10,IF(N29<=누적시수11,11,IF(N29<=누적시수12,12,IF(N29<=누적시수13,13,IF(N29<=누적시수14,14,IF(N29<=누적시수15,15,IF(N29<=누적시수16,16,IF(N29<=누적시수17,17,IF(N29<=누적시수18,18,IF(N29<=누적시수19,19,IF(N29<=누적시수20,20,IF(N29<=누적시수21,21,IF(N29<=누적시수22,22,IF(N29<=누적시수23,23,IF(N29<=누적시수24,24,IF(N29<=누적시수25,25,0)))))))))))))))))))))))))) -> 1 | P29: =MOD(ROW(),9) -> 2 | Q29: =COUNTIF($P$3:P29,"=3") -> 3 | R29: =WORKDAY(기본입력!$H$2,Q29-1,공휴일) -> 45924
A30: =TEXT(R30,"yyyymmdd") -> 20250925 | B30: 0900 | C30: 1740 | E30: 0900 | F30: 1 | G30: =IF(OR(N30="",N30>기본입력!$C$34),"",VLOOKUP(O30,기본입력!$A$9:$F$33,5)) -> 양현수_53778 | H30: =IF(OR(N30="",N30>기본입력!$C$34),"",기본입력!$C$6) -> 1교육실(실습겸용강의실)_243089 | I30: =IF(OR(O30="",N30>기본입력!$C$34),"",VLOOKUP(O30,기본입력!$A$9:$F$33,6,FALSE)) -> 웹 애플리케이션 개발__3 | J30: =IF(F30="2","",LEFT(I30,FIND("_",I30,2)-1)) -> 웹 애플리케이션 개발 | K30: =IF(F30="2","",LEFT(H30,FIND("_",H30,2)-1)) -> 1교육실(실습겸용강의실) | L30: =IF(F30="2","",LEFT(G30,FIND("_",G30,2)-1)) -> 양현수 | N30: =IF(F30="2","",COUNTIF($F$3:$F30,"=1")) -> 25 | O30: =IF(F30="2","",IF(N30<=누적시수1,1,IF(N30<=누적시수2,2,IF(N30<=누적시수3,3,IF(N30<=누적시수4,4,IF(N30<=누적시수5,5,IF(N30<=누적시수6,6,IF(N30<=누적시수7,7,IF(N30<=누적시수8,8,IF(N30<=누적시수9,9,IF(N30<=누적시수10,10,IF(N30<=누적시수11,11,IF(N30<=누적시수12,12,IF(N30<=누적시수13,13,IF(N30<=누적시수14,14,IF(N30<=누적시수15,15,IF(N30<=누적시수16,16,IF(N30<=누적시수17,17,IF(N30<=누적시수18,18,IF(N30<=누적시수19,19,IF(N30<=누적시수20,20,IF(N30<=누적시수21,21,IF(N30<=누적시수22,22,IF(N30<=누적시수23,23,IF(N30<=누적시수24,24,IF(N30<=누적시수25,25,0)))))))))))))))))))))))))) -> 1 | P30: =MOD(ROW(),9) -> 3 | Q30: =COUNTIF($P$3:P30,"=3") -> 4 | R30: =WORKDAY(기본입력!$H$2,Q30-1,공휴일) -> 45925
A31: =TEXT(R31,"yyyymmdd") -> 20250925 | B31: 0900 | C31: 1740 | E31: 1000 | F31: 1 | G31: =IF(OR(N31="",N31>기본입력!$C$34),"",VLOOKUP(O31,기본입력!$A$9:$F$33,5)) -> 양현수_53778 | H31: =IF(OR(N31="",N31>기본입력!$C$34),"",기본입력!$C$6) -> 1교육실(실습겸용강의실)_243089 | I31: =IF(OR(O31="",N31>기본입력!$C$34),"",VLOOKUP(O31,기본입력!$A$9:$F$33,6,FALSE)) -> 웹 애플리케이션 개발__3 | J31: =IF(F31="2","",LEFT(I31,FIND("_",I31,2)-1)) -> 웹 애플리케이션 개발 | K31: =IF(F31="2","",LEFT(H31,FIND("_",H31,2)-1)) -> 1교육실(실습겸용강의실) | L31: =IF(F31="2","",LEFT(G31,FIND("_",G31,2)-1)) -> 양현수 | N31: =IF(F31="2","",COUNTIF($F$3:$F31,"=1")) -> 26 | O31: =IF(F31="2","",IF(N31<=누적시수1,1,IF(N31<=누적시수2,2,IF(N31<=누적시수3,3,IF(N31<=누적시수4,4,IF(N31<=누적시수5,5,IF(N31<=누적시수6,6,IF(N31<=누적시수7,7,IF(N31<=누적시수8,8,IF(N31<=누적시수9,9,IF(N31<=누적시수10,10,IF(N31<=누적시수11,11,IF(N31<=누적시수12,12,IF(N31<=누적시수13,13,IF(N31<=누적시수14,14,IF(N31<=누적시수15,15,IF(N31<=누적시수16,16,IF(N31<=누적시수17,17,IF(N31<=누적시수18,18,IF(N31<=누적시수19,19,IF(N31<=누적시수20,20,IF(N31<=누적시수21,21,IF(N31<=누적시수22,22,IF(N31<=누적시수23,23,IF(N31<=누적시수24,24,IF(N31<=누적시수25,25,0)))))))))))))))))))))))))) -> 1 | P31: =MOD(ROW(),9) -> 4 | Q31: =COUNTIF($P$3:P31,"=3") -> 4 | R31: =WORKDAY(기본입력!$H$2,Q31-1,공휴일) -> 45925
A32: =TEXT(R32,"yyyymmdd") -> 20250925 | B32: 0900 | C32: 1740 | E32: 1100 | F32: 1 | G32: =IF(OR(N32="",N32>기본입력!$C$34),"",VLOOKUP(O32,기본입력!$A$9:$F$33,5)) -> 양현수_53778 | H32: =IF(OR(N32="",N32>기본입력!$C$34),"",기본입력!$C$6) -> 1교육실(실습겸용강의실)_243089 | I32: =IF(OR(O32="",N32>기본입력!$C$34),"",VLOOKUP(O32,기본입력!$A$9:$F$33,6,FALSE)) -> 웹 애플리케이션 개발__3 | J32: =IF(F32="2","",LEFT(I32,FIND("_",I32,2)-1)) -> 웹 애플리케이션 개발 | K32: =IF(F32="2","",LEFT(H32,FIND("_",H32,2)-1)) -> 1교육실(실습겸용강의실) | L32: =IF(F32="2","",LEFT(G32,FIND("_",G32,2)-1)) -> 양현수 | N32: =IF(F32="2","",COUNTIF($F$3:$F32,"=1")) -> 27 | O32: =IF(F32="2","",IF(N32<=누적시수1,1,IF(N32<=누적시수2,2,IF(N32<=누적시수3,3,IF(N32<=누적시수4,4,IF(N32<=누적시수5,5,IF(N32<=누적시수6,6,IF(N32<=누적시수7,7,IF(N32<=누적시수8,8,IF(N32<=누적시수9,9,IF(N32<=누적시수10,10,IF(N32<=누적시수11,11,IF(N32<=누적시수12,12,IF(N32<=누적시수13,13,IF(N32<=누적시수14,14,IF(N32<=누적시수15,15,IF(N32<=누적시수16,16,IF(N32<=누적시수17,17,IF(N32<=누적시수18,18,IF(N32<=누적시수19,19,IF(N32<=누적시수20,20,IF(N32<=누적시수21,21,IF(N32<=누적시수22,22,IF(N32<=누적시수23,23,IF(N32<=누적시수24,24,IF(N32<=누적시수25,25,0)))))))))))))))))))))))))) -> 1 | P32: =MOD(ROW(),9) -> 5 | Q32: =COUNTIF($P$3:P32,"=3") -> 4 | R32: =WORKDAY(기본입력!$H$2,Q32-1,공휴일) -> 45925
A33: =TEXT(R33,"yyyymmdd") -> 20250925 | B33: 0900 | C33: 1740 | E33: 1200 | F33: 1 | G33: =IF(OR(N33="",N33>기본입력!$C$34),"",VLOOKUP(O33,기본입력!$A$9:$F$33,5)) -> 양현수_53778 | H33: =IF(OR(N33="",N33>기본입력!$C$34),"",기본입력!$C$6) -> 1교육실(실습겸용강의실)_243089 | I33: =IF(OR(O33="",N33>기본입력!$C$34),"",VLOOKUP(O33,기본입력!$A$9:$F$33,6,FALSE)) -> 웹 애플리케이션 개발__3 | J33: =IF(F33="2","",LEFT(I33,FIND("_",I33,2)-1)) -> 웹 애플리케이션 개발 | K33: =IF(F33="2","",LEFT(H33,FIND("_",H33,2)-1)) -> 1교육실(실습겸용강의실) | L33: =IF(F33="2","",LEFT(G33,FIND("_",G33,2)-1)) -> 양현수 | N33: =IF(F33="2","",COUNTIF($F$3:$F33,"=1")) -> 28 | O33: =IF(F33="2","",IF(N33<=누적시수1,1,IF(N33<=누적시수2,2,IF(N33<=누적시수3,3,IF(N33<=누적시수4,4,IF(N33<=누적시수5,5,IF(N33<=누적시수6,6,IF(N33<=누적시수7,7,IF(N33<=누적시수8,8,IF(N33<=누적시수9,9,IF(N33<=누적시수10,10,IF(N33<=누적시수11,11,IF(N33<=누적시수12,12,IF(N33<=누적시수13,13,IF(N33<=누적시수14,14,IF(N33<=누적시수15,15,IF(N33<=누적시수16,16,IF(N33<=누적시수17,17,IF(N33<=누적시수18,18,IF(N33<=누적시수19,19,IF(N33<=누적시수20,20,IF(N33<=누적시수21,21,IF(N33<=누적시수22,22,IF(N33<=누적시수23,23,IF(N33<=누적시수24,24,IF(N33<=누적시수25,25,0)))))))))))))))))))))))))) -> 1 | P33: =MOD(ROW(),9) -> 6 | Q33: =COUNTIF($P$3:P33,"=3") -> 4 | R33: =WORKDAY(기본입력!$H$2,Q33-1,공휴일) -> 45925
A34: =TEXT(R34,"yyyymmdd") -> 20250925 | B34: 0900 | C34: 1740 | E34: 1300 | F34: 2 | G34: =IF(OR(N34="",N34>기본입력!$C$34),"",VLOOKUP(O34,기본입력!$A$9:$F$33,5)) | H34: =IF(OR(N34="",N34>기본입력!$C$34),"",기본입력!$C$6) | I34: =IF(OR(O34="",N34>기본입력!$C$34),"",VLOOKUP(O34,기본입력!$A$9:$F$33,6,FALSE)) | J34: =IF(F34="2","",LEFT(I34,FIND("_",I34,2)-1)) | K34: =IF(F34="2","",LEFT(H34,FIND("_",H34,2)-1)) | L34: =IF(F34="2","",LEFT(G34,FIND("_",G34,2)-1)) | N34: =IF(F34="2","",COUNTIF($F$3:$F34,"=1")) | O34: =IF(F34="2","",IF(N34<=누적시수1,1,IF(N34<=누적시수2,2,IF(N34<=누적시수3,3,IF(N34<=누적시수4,4,IF(N34<=누적시수5,5,IF(N34<=누적시수6,6,IF(N34<=누적시수7,7,IF(N34<=누적시수8,8,IF(N34<=누적시수9,9,IF(N34<=누적시수10,10,IF(N34<=누적시수11,11,IF(N34<=누적시수12,12,IF(N34<=누적시수13,13,IF(N34<=누적시수14,14,IF(N34<=누적시수15,15,IF(N34<=누적시수16,16,IF(N34<=누적시수17,17,IF(N34<=누적시수18,18,IF(N34<=누적시수19,19,IF(N34<=누적시수20,20,IF(N34<=누적시수21,21,IF(N34<=누적시수22,22,IF(N34<=누적시수23,23,IF(N34<=누적시수24,24,IF(N34<=누적시수25,25,0)))))))))))))))))))))))))) | P34: =MOD(ROW(),9) -> 7 | Q34: =COUNTIF($P$3:P34,"=3") -> 4 | R34: =WORKDAY(기본입력!$H$2,Q34-1,공휴일) -> 45925
A35: =TEXT(R35,"yyyymmdd") -> 20250925 | B35: 0900 | C35: 1740 | E35: 1340 | F35: 1 | G35: =IF(OR(N35="",N35>기본입력!$C$34),"",VLOOKUP(O35,기본입력!$A$9:$F$33,5)) -> 양현수_53778 | H35: =IF(OR(N35="",N35>기본입력!$C$34),"",기본입력!$C$6) -> 1교육실(실습겸용강의실)_243089 | I35: =IF(OR(O35="",N35>기본입력!$C$34),"",VLOOKUP(O35,기본입력!$A$9:$F$33,6,FALSE)) -> 웹 애플리케이션 개발__3 | J35: =IF(F35="2","",LEFT(I35,FIND("_",I35,2)-1)) -> 웹 애플리케이션 개발 | K35: =IF(F35="2","",LEFT(H35,FIND("_",H35,2)-1)) -> 1교육실(실습겸용강의실) | L35: =IF(F35="2","",LEFT(G35,FIND("_",G35,2)-1)) -> 양현수 | N35: =IF(F35="2","",COUNTIF($F$3:$F35,"=1")) -> 29 | O35: =IF(F35="2","",IF(N35<=누적시수1,1,IF(N35<=누적시수2,2,IF(N35<=누적시수3,3,IF(N35<=누적시수4,4,IF(N35<=누적시수5,5,IF(N35<=누적시수6,6,IF(N35<=누적시수7,7,IF(N35<=누적시수8,8,IF(N35<=누적시수9,9,IF(N35<=누적시수10,10,IF(N35<=누적시수11,11,IF(N35<=누적시수12,12,IF(N35<=누적시수13,13,IF(N35<=누적시수14,14,IF(N35<=누적시수15,15,IF(N35<=누적시수16,16,IF(N35<=누적시수17,17,IF(N35<=누적시수18,18,IF(N35<=누적시수19,19,IF(N35<=누적시수20,20,IF(N35<=누적시수21,21,IF(N35<=누적시수22,22,IF(N35<=누적시수23,23,IF(N35<=누적시수24,24,IF(N35<=누적시수25,25,0)))))))))))))))))))))))))) -> 1 | P35: =MOD(ROW(),9) -> 8 | Q35: =COUNTIF($P$3:P35,"=3") -> 4 | R35: =WORKDAY(기본입력!$H$2,Q35-1,공휴일) -> 45925
A36: =TEXT(R36,"yyyymmdd") -> 20250925 | B36: 0900 | C36: 1740 | E36: 1440 | F36: 1 | G36: =IF(OR(N36="",N36>기본입력!$C$34),"",VLOOKUP(O36,기본입력!$A$9:$F$33,5)) -> 양현수_53778 | H36: =IF(OR(N36="",N36>기본입력!$C$34),"",기본입력!$C$6) -> 1교육실(실습겸용강의실)_243089 | I36: =IF(OR(O36="",N36>기본입력!$C$34),"",VLOOKUP(O36,기본입력!$A$9:$F$33,6,FALSE)) -> 웹 애플리케이션 개발__3 | J36: =IF(F36="2","",LEFT(I36,FIND("_",I36,2)-1)) -> 웹 애플리케이션 개발 | K36: =IF(F36="2","",LEFT(H36,FIND("_",H36,2)-1)) -> 1교육실(실습겸용강의실) | L36: =IF(F36="2","",LEFT(G36,FIND("_",G36,2)-1)) -> 양현수 | N36: =IF(F36="2","",COUNTIF($F$3:$F36,"=1")) -> 30 | O36: =IF(F36="2","",IF(N36<=누적시수1,1,IF(N36<=누적시수2,2,IF(N36<=누적시수3,3,IF(N36<=누적시수4,4,IF(N36<=누적시수5,5,IF(N36<=누적시수6,6,IF(N36<=누적시수7,7,IF(N36<=누적시수8,8,IF(N36<=누적시수9,9,IF(N36<=누적시수10,10,IF(N36<=누적시수11,11,IF(N36<=누적시수12,12,IF(N36<=누적시수13,13,IF(N36<=누적시수14,14,IF(N36<=누적시수15,15,IF(N36<=누적시수16,16,IF(N36<=누적시수17,17,IF(N36<=누적시수18,18,IF(N36<=누적시수19,19,IF(N36<=누적시수20,20,IF(N36<=누적시수21,21,IF(N36<=누적시수22,22,IF(N36<=누적시수23,23,IF(N36<=누적시수24,24,IF(N36<=누적시수25,25,0)))))))))))))))))))))))))) -> 1 | P36: =MOD(ROW(),9) -> 0 | Q36: =COUNTIF($P$3:P36,"=3") -> 4 | R36: =WORKDAY(기본입력!$H$2,Q36-1,공휴일) -> 45925
A37: =TEXT(R37,"yyyymmdd") -> 20250925 | B37: 0900 | C37: 1740 | E37: 1540 | F37: 1 | G37: =IF(OR(N37="",N37>기본입력!$C$34),"",VLOOKUP(O37,기본입력!$A$9:$F$33,5)) -> 양현수_53778 | H37: =IF(OR(N37="",N37>기본입력!$C$34),"",기본입력!$C$6) -> 1교육실(실습겸용강의실)_243089 | I37: =IF(OR(O37="",N37>기본입력!$C$34),"",VLOOKUP(O37,기본입력!$A$9:$F$33,6,FALSE)) -> 웹 애플리케이션 개발__3 | J37: =IF(F37="2","",LEFT(I37,FIND("_",I37,2)-1)) -> 웹 애플리케이션 개발 | K37: =IF(F37="2","",LEFT(H37,FIND("_",H37,2)-1)) -> 1교육실(실습겸용강의실) | L37: =IF(F37="2","",LEFT(G37,FIND("_",G37,2)-1)) -> 양현수 | N37: =IF(F37="2","",COUNTIF($F$3:$F37,"=1")) -> 31 | O37: =IF(F37="2","",IF(N37<=누적시수1,1,IF(N37<=누적시수2,2,IF(N37<=누적시수3,3,IF(N37<=누적시수4,4,IF(N37<=누적시수5,5,IF(N37<=누적시수6,6,IF(N37<=누적시수7,7,IF(N37<=누적시수8,8,IF(N37<=누적시수9,9,IF(N37<=누적시수10,10,IF(N37<=누적시수11,11,IF(N37<=누적시수12,12,IF(N37<=누적시수13,13,IF(N37<=누적시수14,14,IF(N37<=누적시수15,15,IF(N37<=누적시수16,16,IF(N37<=누적시수17,17,IF(N37<=누적시수18,18,IF(N37<=누적시수19,19,IF(N37<=누적시수20,20,IF(N37<=누적시수21,21,IF(N37<=누적시수22,22,IF(N37<=누적시수23,23,IF(N37<=누적시수24,24,IF(N37<=누적시수25,25,0)))))))))))))))))))))))))) -> 1 | P37: =MOD(ROW(),9) -> 1 | Q37: =COUNTIF($P$3:P37,"=3") -> 4 | R37: =WORKDAY(기본입력!$H$2,Q37-1,공휴일) -> 45925
A38: =TEXT(R38,"yyyymmdd") -> 20250925 | B38: 0900 | C38: 1740 | E38: 1640 | F38: 1 | G38: =IF(OR(N38="",N38>기본입력!$C$34),"",VLOOKUP(O38,기본입력!$A$9:$F$33,5)) -> 양현수_53778 | H38: =IF(OR(N38="",N38>기본입력!$C$34),"",기본입력!$C$6) -> 1교육실(실습겸용강의실)_243089 | I38: =IF(OR(O38="",N38>기본입력!$C$34),"",VLOOKUP(O38,기본입력!$A$9:$F$33,6,FALSE)) -> 웹 애플리케이션 개발__3 | J38: =IF(F38="2","",LEFT(I38,FIND("_",I38,2)-1)) -> 웹 애플리케이션 개발 | K38: =IF(F38="2","",LEFT(H38,FIND("_",H38,2)-1)) -> 1교육실(실습겸용강의실) | L38: =IF(F38="2","",LEFT(G38,FIND("_",G38,2)-1)) -> 양현수 | N38: =IF(F38="2","",COUNTIF($F$3:$F38,"=1")) -> 32 | O38: =IF(F38="2","",IF(N38<=누적시수1,1,IF(N38<=누적시수2,2,IF(N38<=누적시수3,3,IF(N38<=누적시수4,4,IF(N38<=누적시수5,5,IF(N38<=누적시수6,6,IF(N38<=누적시수7,7,IF(N38<=누적시수8,8,IF(N38<=누적시수9,9,IF(N38<=누적시수10,10,IF(N38<=누적시수11,11,IF(N38<=누적시수12,12,IF(N38<=누적시수13,13,IF(N38<=누적시수14,14,IF(N38<=누적시수15,15,IF(N38<=누적시수16,16,IF(N38<=누적시수17,17,IF(N38<=누적시수18,18,IF(N38<=누적시수19,19,IF(N38<=누적시수20,20,IF(N38<=누적시수21,21,IF(N38<=누적시수22,22,IF(N38<=누적시수23,23,IF(N38<=누적시수24,24,IF(N38<=누적시수25,25,0)))))))))))))))))))))))))) -> 1 | P38: =MOD(ROW(),9) -> 2 | Q38: =COUNTIF($P$3:P38,"=3") -> 4 | R38: =WORKDAY(기본입력!$H$2,Q38-1,공휴일) -> 45925
A39: =TEXT(R39,"yyyymmdd") -> 20250926 | B39: 0900 | C39: 1740 | E39: 0900 | F39: 1 | G39: =IF(OR(N39="",N39>기본입력!$C$34),"",VLOOKUP(O39,기본입력!$A$9:$F$33,5)) -> 양현수_53778 | H39: =IF(OR(N39="",N39>기본입력!$C$34),"",기본입력!$C$6) -> 1교육실(실습겸용강의실)_243089 | I39: =IF(OR(O39="",N39>기본입력!$C$34),"",VLOOKUP(O39,기본입력!$A$9:$F$33,6,FALSE)) -> 웹 애플리케이션 개발__3 | J39: =IF(F39="2","",LEFT(I39,FIND("_",I39,2)-1)) -> 웹 애플리케이션 개발 | K39: =IF(F39="2","",LEFT(H39,FIND("_",H39,2)-1)) -> 1교육실(실습겸용강의실) | L39: =IF(F39="2","",LEFT(G39,FIND("_",G39,2)-1)) -> 양현수 | N39: =IF(F39="2","",COUNTIF($F$3:$F39,"=1")) -> 33 | O39: =IF(F39="2","",IF(N39<=누적시수1,1,IF(N39<=누적시수2,2,IF(N39<=누적시수3,3,IF(N39<=누적시수4,4,IF(N39<=누적시수5,5,IF(N39<=누적시수6,6,IF(N39<=누적시수7,7,IF(N39<=누적시수8,8,IF(N39<=누적시수9,9,IF(N39<=누적시수10,10,IF(N39<=누적시수11,11,IF(N39<=누적시수12,12,IF(N39<=누적시수13,13,IF(N39<=누적시수14,14,IF(N39<=누적시수15,15,IF(N39<=누적시수16,16,IF(N39<=누적시수17,17,IF(N39<=누적시수18,18,IF(N39<=누적시수19,19,IF(N39<=누적시수20,20,IF(N39<=누적시수21,21,IF(N39<=누적시수22,22,IF(N39<=누적시수23,23,IF(N39<=누적시수24,24,IF(N39<=누적시수25,25,0)))))))))))))))))))))))))) -> 1 | P39: =MOD(ROW(),9) -> 3 | Q39: =COUNTIF($P$3:P39,"=3") -> 5 | R39: =WORKDAY(기본입력!$H$2,Q39-1,공휴일) -> 45926
A40: =TEXT(R40,"yyyymmdd") -> 20250926 | B40: 0900 | C40: 1740 | E40: 1000 | F40: 1 | G40: =IF(OR(N40="",N40>기본입력!$C$34),"",VLOOKUP(O40,기본입력!$A$9:$F$33,5)) -> 양현수_53778 | H40: =IF(OR(N40="",N40>기본입력!$C$34),"",기본입력!$C$6) -> 1교육실(실습겸용강의실)_243089 | I40: =IF(OR(O40="",N40>기본입력!$C$34),"",VLOOKUP(O40,기본입력!$A$9:$F$33,6,FALSE)) -> 웹 애플리케이션 개발__3 | J40: =IF(F40="2","",LEFT(I40,FIND("_",I40,2)-1)) -> 웹 애플리케이션 개발 | K40: =IF(F40="2","",LEFT(H40,FIND("_",H40,2)-1)) -> 1교육실(실습겸용강의실) | L40: =IF(F40="2","",LEFT(G40,FIND("_",G40,2)-1)) -> 양현수 | N40: =IF(F40="2","",COUNTIF($F$3:$F40,"=1")) -> 34 | O40: =IF(F40="2","",IF(N40<=누적시수1,1,IF(N40<=누적시수2,2,IF(N40<=누적시수3,3,IF(N40<=누적시수4,4,IF(N40<=누적시수5,5,IF(N40<=누적시수6,6,IF(N40<=누적시수7,7,IF(N40<=누적시수8,8,IF(N40<=누적시수9,9,IF(N40<=누적시수10,10,IF(N40<=누적시수11,11,IF(N40<=누적시수12,12,IF(N40<=누적시수13,13,IF(N40<=누적시수14,14,IF(N40<=누적시수15,15,IF(N40<=누적시수16,16,IF(N40<=누적시수17,17,IF(N40<=누적시수18,18,IF(N40<=누적시수19,19,IF(N40<=누적시수20,20,IF(N40<=누적시수21,21,IF(N40<=누적시수22,22,IF(N40<=누적시수23,23,IF(N40<=누적시수24,24,IF(N40<=누적시수25,25,0)))))))))))))))))))))))))) -> 1 | P40: =MOD(ROW(),9) -> 4 | Q40: =COUNTIF($P$3:P40,"=3") -> 5 | R40: =WORKDAY(기본입력!$H$2,Q40-1,공휴일) -> 45926
...

Sheet 시간표(상용)
B1: 1 | G1: 2 | L1: 3 | Q1: 4 | V1: 5 | AA1: 6 | AF1: 7 | AK1: 8 | AP1: 9 | AU1: 10 | AZ1: 11 | BE1: 12 | BJ1: 13 | BO1: 14 | BT1: 15 | BY1: 16 | CD1: 17 | CI1: 18 | CN1: 19 | CS1: 20 | CX1: 21 | DC1: 22 | DH1: 23 | DM1: 24 | DR1: 25 | DW1: 26 | EB1: 27 | EG1: 28 | EL1: 29
B2: =TEXT(B6,"yyyy년 m월 ")&B1&"주차 시간표" -> 2025년 9월 1주차 시간표 | G2: =TEXT(G6,"yyyy년 m월 ")&G1&"주차 시간표" -> 2025년 9월 2주차 시간표 | L2: =TEXT(L6,"yyyy년 m월 ")&L1&"주차 시간표" -> 2025년 10월 3주차 시간표 | Q2: =TEXT(Q6,"yyyy년 m월 ")&Q1&"주차 시간표" -> 2025년 10월 4주차 시간표 | V2: =TEXT(V6,"yyyy년 m월 ")&V1&"주차 시간표" -> 2025년 10월 5주차 시간표 | AA2: =TEXT(AA6,"yyyy년 m월 ")&AA1&"주차 시간표" -> 2025년 10월 6주차 시간표 | AF2: =TEXT(AF6,"yyyy년 m월 ")&AF1&"주차 시간표" -> 2025년 11월 7주차 시간표 | AK2: =TEXT(AK6,"yyyy년 m월 ")&AK1&"주차 시간표" -> 2025년 11월 8주차 시간표 | AP2: =TEXT(AP6,"yyyy년 m월 ")&AP1&"주차 시간표" -> 2025년 11월 9주차 시간표 | AU2: =TEXT(AU6,"yyyy년 m월 ")&AU1&"주차 시간표" -> 2025년 11월 10주차 시간표 | AZ2: =TEXT(AZ6,"yyyy년 m월 ")&AZ1&"주차 시간표" -> 2025년 12월 11주차 시간표 | BE2: =TEXT(BE6,"yyyy년 m월 ")&BE1&"주차 시간표" -> 2025년 12월 12주차 시간표 | BJ2: =TEXT(BJ6,"yyyy년 m월 ")&BJ1&"주차 시간표" -> 2025년 12월 13주차 시간표 | BO2: =TEXT(BO6,"yyyy년 m월 ")&BO1&"주차 시간표" -> 2025년 12월 14주차 시간표 | BT2: =TEXT(BT6,"yyyy년 m월 ")&BT1&"주차 시간표" -> 2025년 12월 15주차 시간표 | BY2: =TEXT(BY6,"yyyy년 m월 ")&BY1&"주차 시간표" -> 2026년 1월 16주차 시간표 | CD2: =TEXT(CD6,"yyyy년 m월 ")&CD1&"주차 시간표" -> 2026년 1월 17주차 시간표 | CI2: =TEXT(CI6,"yyyy년 m월 ")&CI1&"주차 시간표" -> 2026년 1월 18주차 시간표 | CN2: =TEXT(CN6,"yyyy년 m월 ")&CN1&"주차 시간표" -> 2026년 1월 19주차 시간표 | CS2: =TEXT(CS6,"yyyy년 m월 ")&CS1&"주차 시간표" -> 2026년 2월 20주차 시간표 | CX2: =TEXT(CX6,"yyyy년 m월 ")&CX1&"주차 시간표" -> 2026년 2월 21주차 시간표 | DC2: =TEXT(DC6,"yyyy년 m월 ")&DC1&"주차 시간표" -> 2026년 2월 22주차 시간표 | DH2: =TEXT(DH6,"yyyy년 m월 ")&DH1&"주차 시간표" -> 2026년 2월 23주차 시간표 | DM2: =TEXT(DM6,"yyyy년 m월 ")&DM1&"주차 시간표" -> 2026년 3월 24주차 시간표 | DR2: =TEXT(DM6,"yyyy년 m월 ")&DM1&"주차 시간표" -> 2026년 3월 24주차 시간표 | DW2: =TEXT(DW6,"yyyy년 m월 ")&DW1&"주차 시간표" -> 2026년 3월 26주차 시간표 | EB2: =TEXT(EB6,"yyyy년 m월 ")&EB1&"주차 시간표" -> 2026년 3월 27주차 시간표 | EG2: =TEXT(EG6,"yyyy년 m월 ")&EG1&"주차 시간표" -> 2026년 3월 28주차 시간표 | EL2: =TEXT(EL6,"yyyy년 m월 ")&EL1&"주차 시간표" -> 2026년 4월 29주차 시간표
B3: =기본입력!$C$1&" ("&기본입력!$C$2&")" -> 인공지능(AI),빅데이터 활용 웹솔루션 개발자 양성(Python, Java) (2025.09.22~2026.03.25) | G3: =기본입력!$C$1&" ("&기본입력!$C$2&")" -> 인공지능(AI),빅데이터 활용 웹솔루션 개발자 양성(Python, Java) (2025.09.22~2026.03.25) | L3: =기본입력!$C$1&" ("&기본입력!$C$2&")" -> 인공지능(AI),빅데이터 활용 웹솔루션 개발자 양성(Python, Java) (2025.09.22~2026.03.25) | Q3: =기본입력!$C$1&" ("&기본입력!$C$2&")" -> 인공지능(AI),빅데이터 활용 웹솔루션 개발자 양성(Python, Java) (2025.09.22~2026.03.25) | V3: =기본입력!$C$1&" ("&기본입력!$C$2&")" -> 인공지능(AI),빅데이터 활용 웹솔루션 개발자 양성(Python, Java) (2025.09.22~2026.03.25) | AA3: =기본입력!$C$1&" ("&기본입력!$C$2&")" -> 인공지능(AI),빅데이터 활용 웹솔루션 개발자 양성(Python, Java) (2025.09.22~2026.03.25) | AF3: =기본입력!$C$1&" ("&기본입력!$C$2&")" -> 인공지능(AI),빅데이터 활용 웹솔루션 개발자 양성(Python, Java) (2025.09.22~2026.03.25) | AK3: =기본입력!$C$1&" ("&기본입력!$C$2&")" -> 인공지능(AI),빅데이터 활용 웹솔루션 개발자 양성(Python, Java) (2025.09.22~2026.03.25) | AP3: =기본입력!$C$1&" ("&기본입력!$C$2&")" -> 인공지능(AI),빅데이터 활용 웹솔루션 개발자 양성(Python, Java) (2025.09.22~2026.03.25) | AU3: =기본입력!$C$1&" ("&기본입력!$C$2&")" -> 인공지능(AI),빅데이터 활용 웹솔루션 개발자 양성(Python, Java) (2025.09.22~2026.03.25) | AZ3: =기본입력!$C$1&" ("&기본입력!$C$2&")" -> 인공지능(AI),빅데이터 활용 웹솔루션 개발자 양성(Python, Java) (2025.09.22~2026.03.25) | BE3: =기본입력!$C$1&" ("&기본입력!$C$2&")" -> 인공지능(AI),빅데이터 활용 웹솔루션 개발자 양성(Python, Java) (2025.09.22~2026.03.25) | BJ3: =기본입력!$C$1&" ("&기본입력!$C$2&")" -> 인공지능(AI),빅데이터 활용 웹솔루션 개발자 양성(Python, Java) (2025.09.22~2026.03.25) | BO3: =기본입력!$C$1&" ("&기본입력!$C$2&")" -> 인공지능(AI),빅데이터 활용 웹솔루션 개발자 양성(Python, Java) (2025.09.22~2026.03.25) | BT3: =기본입력!$C$1&" ("&기본입력!$C$2&")" -> 인공지능(AI),빅데이터 활용 웹솔루션 개발자 양성(Python, Java) (2025.09.22~2026.03.25) | BY3: =기본입력!$C$1&" ("&기본입력!$C$2&")" -> 인공지능(AI),빅데이터 활용 웹솔루션 개발자 양성(Python, Java) (2025.09.22~2026.03.25) | CD3: =기본입력!$C$1&" ("&기본입력!$C$2&")" -> 인공지능(AI),빅데이터 활용 웹솔루션 개발자 양성(Python, Java) (2025.09.22~2026.03.25) | CI3: =기본입력!$C$1&" ("&기본입력!$C$2&")" -> 인공지능(AI),빅데이터 활용 웹솔루션 개발자 양성(Python, Java) (2025.09.22~2026.03.25) | CN3: =기본입력!$C$1&" ("&기본입력!$C$2&")" -> 인공지능(AI),빅데이터 활용 웹솔루션 개발자 양성(Python, Java) (2025.09.22~2026.03.25) | CS3: =기본입력!$C$1&" ("&기본입력!$C$2&")" -> 인공지능(AI),빅데이터 활용 웹솔루션 개발자 양성(Python, Java) (2025.09.22~2026.03.25) | CX3: =기본입력!$C$1&" ("&기본입력!$C$2&")" -> 인공지능(AI),빅데이터 활용 웹솔루션 개발자 양성(Python, Java) (2025.09.22~2026.03.25) | DC3: =기본입력!$C$1&" ("&기본입력!$C$2&")" -> 인공지능(AI),빅데이터 활용 웹솔루션 개발자 양성(Python, Java) (2025.09.22~2026.03.25) | DH3: =기본입력!$C$1&" ("&기본입력!$C$2&")" -> 인공지능(AI),빅데이터 활용 웹솔루션 개발자 양성(Python, Java) (2025.09.22~2026.03.25) | DM3: =기본입력!$C$1&" ("&기본입력!$C$2&")" -> 인공지능(AI),빅데이터 활용 웹솔루션 개발자 양성(Python, Java) (2025.09.22~2026.03.25) | DR3: =기본입력!$C$1&" ("&기본입력!$C$2&")" -> 인공지능(AI),빅데이터 활용 웹솔루션 개발자 양성(Python, Java) (2025.09.22~2026.03.25) | DW3: =기본입력!$C$1&" ("&기본입력!$C$2&")" -> 인공지능(AI),빅데이터 활용 웹솔루션 개발자 양성(Python, Java) (2025.09.22~2026.03.25) | EB3: =기본입력!$C$1&" ("&기본입력!$C$2&")" -> 인공지능(AI),빅데이터 활용 웹솔루션 개발자 양성(Python, Java) (2025.09.22~2026.03.25) | EG3: =기본입력!$C$1&" ("&기본입력!$C$2&")" -> 인공지능(AI),빅데이터 활용 웹솔루션 개발자 양성(Python, Java) (2025.09.22~2026.03.25) | EL3: =기본입력!$C$1&" ("&기본입력!$C$2&")" -> 인공지능(AI),빅데이터 활용 웹솔루션 개발자 양성(Python, Java) (2025.09.22~2026.03.25)
B4: =NETWORKDAYS(시작일,B6,공휴일) -> 1 | C4: =NETWORKDAYS(시작일,C6,공휴일) -> 2 | D4: =NETWORKDAYS(시작일,D6,공휴일) -> 3 | E4: =NETWORKDAYS(시작일,E6,공휴일) -> 4 | F4: =NETWORKDAYS(시작일,F6,공휴일) -> 5 | G4: =NETWORKDAYS(시작일,G6,공휴일) -> 6 | H4: =NETWORKDAYS(시작일,H6,공휴일) -> 7 | I4: =NETWORKDAYS(시작일,I6,공휴일) -> 8 | ... EP4: =NETWORKDAYS(시작일,EP6,공휴일) -> 134
A5: 교시 시간 | B5: =TEXT(B6,"aaaa") -> 월요일 | C5: =TEXT(C6,"aaaa") -> 화요일 | D5: =TEXT(D6,"aaaa") -> 수요일 | E5: =TEXT(E6,"aaaa") -> 목요일 | F5: =TEXT(F6,"aaaa") -> 금요일 | G5: =TEXT(G6,"aaaa") -> 월요일 | H5: =TEXT(H6,"aaaa") -> 화요일 | I5: =TEXT(I6,"aaaa") -> 수요일 | ... EP5: =TEXT(EP6,"aaaa") -> 금요일
B6: =시작주월요일 -> 45922 | C6: =WORKDAY(시작주월요일,COLUMN()-2) -> 45923 | D6: =WORKDAY(시작주월요일,COLUMN()-2) -> 45924 | E6: =WORKDAY(시작주월요일,COLUMN()-2) -> 45925 | F6: =WORKDAY(시작주월요일,COLUMN()-2) -> 45926 | G6: =WORKDAY(시작주월요일,COLUMN()-2) -> 45929 | H6: =WORKDAY(시작주월요일,COLUMN()-2) -> 45930 | I6: =WORKDAY(시작주월요일,COLUMN()-2) -> 45931 | J6: =WORKDAY(시작주월요일,COLUMN()-2) -> 45932 | ... EP6: =WORKDAY(시작주월요일,COLUMN()-2) -> 46122
A7: 1교시 09:00 ~ 09:50 | B7: =IF(OR(B4<0,B4=A4,ISERROR(INDEX(세부시간표!$A$3:$L$1183,9*B4-8,10))),"",INDEX(세부시간표!$A$3:$L$1183,9*B4-8,10)) -> 웹 애플리케이션 개발 | C7: =IF(OR(C4<0,C4=B4,ISERROR(INDEX(세부시간표!$A$3:$L$1183,9*C4-8,10))),"",INDEX(세부시간표!$A$3:$L$1183,9*C4-8,10)) -> 웹 애플리케이션 개발 | D7: =IF(OR(D4<0,D4=C4,ISERROR(INDEX(세부시간표!$A$3:$L$1183,9*D4-8,10))),"",INDEX(세부시간표!$A$3:$L$1183,9*D4-8,10)) -> 웹 애플리케이션 개발 | E7: =IF(OR(E4<0,E4=D4,ISERROR(INDEX(세부시간표!$A$3:$L$1183,9*E4-8,10))),"",INDEX(세부시간표!$A$3:$L$1183,9*E4-8,10)) -> 웹 애플리케이션 개발 | F7: =IF(OR(F4<0,F4=E4,ISERROR(INDEX(세부시간표!$A$3:$L$1183,9*F4-8,10))),"",INDEX(세부시간표!$A$3:$L$1183,9*F4-8,10)) -> 웹 애플리케이션 개발 | G7: =IF(OR(G4<0,G4=F4,ISERROR(INDEX(세부시간표!$A$3:$L$1183,9*G4-8,10))),"",INDEX(세부시간표!$A$3:$L$1183,9*G4-8,10)) -> 웹 애플리케이션 개발 | H7: =IF(OR(H4<0,H4=G4,ISERROR(INDEX(세부시간표!$A$3:$L$1183,9*H4-8,10))),"",INDEX(세부시간표!$A$3:$L$1183,9*H4-8,10)) -> 웹 애플리케이션 개발 | I7: =IF(OR(I4<0,I4=H4,ISERROR(INDEX(세부시간표!$A$3:$L$1183,9*I4-8,10))),"",INDEX(세부시간표!$A$3:$L$1183,9*I4-8,10)) -> 웹 애플리케이션 개발 | ... EP7: =IF(OR(EP4<0,EP4=EO4,ISERROR(INDEX(세부시간표!$A$3:$L$1183,9*EP4-8,10))),"",INDEX(세부시간표!$A$3:$L$1183,9*EP4-8,10))
B8: =B7 -> 웹 애플리케이션 개발 | C8: =C7 -> 웹 애플리케이션 개발 | D8: =D7 -> 웹 애플리케이션 개발 | E8: =E7 -> 웹 애플리케이션 개발 | F8: =F7 -> 웹 애플리케이션 개발 | G8: =G7 -> 웹 애플리케이션 개발 | H8: =H7 -> 웹 애플리케이션 개발 | I8: =I7 -> 웹 애플리케이션 개발 | ... EP8: =EP7
B9: =IF(OR(B4<0,B4=A4,ISERROR(INDEX(세부시간표!$A$3:$L$1183,9*B4-8,11))),"",LEFT(INDEX(세부시간표!$A$3:$L$1183,9*B4-8,11),4)) -> 1교육실 | C9: =IF(OR(C4<0,C4=B4,ISERROR(INDEX(세부시간표!$A$3:$L$1183,9*C4-8,11))),"",LEFT(INDEX(세부시간표!$A$3:$L$1183,9*C4-8,11),4)) -> 1교육실 | D9: =IF(OR(D4<0,D4=C4,ISERROR(INDEX(세부시간표!$A$3:$L$1183,9*D4-8,11))),"",LEFT(INDEX(세부시간표!$A$3:$L$1183,9*D4-8,11),4)) -> 1교육실 | E9: =IF(OR(E4<0,E4=D4,ISERROR(INDEX(세부시간표!$A$3:$L$1183,9*E4-8,11))),"",LEFT(INDEX(세부시간표!$A$3:$L$1183,9*E4-8,11),4)) -> 1교육실 | F9: =IF(OR(F4<0,F4=E4,ISERROR(INDEX(세부시간표!$A$3:$L$1183,9*F4-8,11))),"",LEFT(INDEX(세부시간표!$A$3:$L$1183,9*F4-8,11),4)) -> 1교육실 | G9: =IF(OR(G4<0,G4=F4,ISERROR(INDEX(세부시간표!$A$3:$L$1183,9*G4-8,11))),"",LEFT(INDEX(세부시간표!$A$3:$L$1183,9*G4-8,11),4)) -> 1교육실 | H9: =IF(OR(H4<0,H4=G4,ISERROR(INDEX(세부시간표!$A$3:$L$1183,9*H4-8,11))),"",LEFT(INDEX(세부시간표!$A$3:$L$1183,9*H4-8,11),4)) -> 1교육실 | I9: =IF(OR(I4<0,I4=H4,ISERROR(INDEX(세부시간표!$A$3:$L$1183,9*I4-8,11))),"",LEFT(INDEX(세부시간표!$A$3:$L$1183,9*I4-8,11),4)) -> 1교육실 | ... EK9: =IF(OR(EK4<0,EK4=EJ4,ISERROR(INDEX(세부시간표!$A$3:$L$1183,9*EK4-8,11))),"",LEFT(INDEX(세부시간표!$A$3:$L$1183,9*EK4-8,11),4)) | EL9: =IF(OR(EL4<0,EL4=EK4,ISERROR(INDEX(세부시간표!$A$3:$L$1183,9*EL4-8,11))),"",INDEX(세부시간표!$A$3:$L$1183,9*EL4-8,11)) | EM9: =IF(OR(EM4<0,EM4=EL4,ISERROR(INDEX(세부시간표!$A$3:$L$1183,9*EM4-8,11))),"",INDEX(세부시간표!$A$3:$L$1183,9*EM4-8,11)) | EN9: =IF(OR(EN4<0,EN4=EM4,ISERROR(INDEX(세부시간표!$A$3:$L$1183,9*EN4-8,11))),"",INDEX(세부시간표!$A$3:$L$1183,9*EN4-8,11)) | EO9: =IF(OR(EO4<0,EO4=EN4,ISERROR(INDEX(세부시간표!$A$3:$L$1183,9*EO4-8,11))),"",INDEX(세부시간표!$A$3:$L$1183,9*EO4-8,11)) | EP9: =IF(OR(EP4<0,EP4=EO4,ISERROR(INDEX(세부시간표!$A$3:$L$1183,9*EP4-8,11))),"",INDEX(세부시간표!$A$3:$L$1183,9*EP4-8,11))
